Workbook

Sheet Báo giá
D1: CÔNG TY CỔ PHẦN DU LỊCH P.S.V TRAVEL
D2: 529 Huỳnh Tấn Phát, Phường Tân Thuận, TP. Hồ Chí Minh · Hotline 0907 870 707
D3: nguyendusit399@gmail.com · psvtravel.com · MST 0314542363 · GP LHQT 79-769/2020/CDLQGVN-GP LHQT
A5: BÁO GIÁ DỊCH VỤ DU LỊCH / SỰ KIỆN DOANH NGHIỆP
A7: Số báo giá: | C7: BG-2026-001 | F7: Ngày lập: | H7: =TODAY() -> 46317
A8: Hiệu lực (ngày): | C8: 15 | F8: Hiệu lực đến: | H8: =IF(H7="","",H7+C8) -> 46332
A10: THÔNG TIN KHÁCH HÀNG & CHƯƠNG TRÌNH
A11: Công ty: | F11: Mã số thuế:
A12: Người liên hệ: | F12: Điện thoại:
A13: Email: | F13: Số khách:
A14: Chương trình: | F14: Điểm đến:
A15: Ngày đi: | F15: Ngày về:
A17: STT | B17: Hạng mục (chọn từ bảng giá hoặc gõ) | C17: Diễn giải | D17: Đơn vị | E17: Số lượng | F17: Số ngày / lần | G17: Đơn giá nhập tay | H17: Đơn giá áp dụng | I17: Thành tiền (VNĐ)
A18: =IF(B18="","",COUNTA($B$18:B18)) | D18: =IF(B18="","",IFERROR(INDEX('Bảng đơn giá'!$D$5:$D$80,MATCH(B18,'Bảng đơn giá'!$C$5:$C$80,0)),"")) | H18: =IF(B18="","",IF(G18<>"",G18,IFERROR(INDEX('Bảng đơn giá'!$E$5:$E$80,MATCH(B18,'Bảng đơn giá'!$C$5:$C$80,0)),0))) | I18: =IF(B18="","",E18*IF(F18="",1,F18)*H18)
A19: =IF(B19="","",COUNTA($B$18:B19)) | D19: =IF(B19="","",IFERROR(INDEX('Bảng đơn giá'!$D$5:$D$80,MATCH(B19,'Bảng đơn giá'!$C$5:$C$80,0)),"")) | H19: =IF(B19="","",IF(G19<>"",G19,IFERROR(INDEX('Bảng đơn giá'!$E$5:$E$80,MATCH(B19,'Bảng đơn giá'!$C$5:$C$80,0)),0))) | I19: =IF(B19="","",E19*IF(F19="",1,F19)*H19)
A20: =IF(B20="","",COUNTA($B$18:B20)) | D20: =IF(B20="","",IFERROR(INDEX('Bảng đơn giá'!$D$5:$D$80,MATCH(B20,'Bảng đơn giá'!$C$5:$C$80,0)),"")) | H20: =IF(B20="","",IF(G20<>"",G20,IFERROR(INDEX('Bảng đơn giá'!$E$5:$E$80,MATCH(B20,'Bảng đơn giá'!$C$5:$C$80,0)),0))) | I20: =IF(B20="","",E20*IF(F20="",1,F20)*H20)
A21: =IF(B21="","",COUNTA($B$18:B21)) | D21: =IF(B21="","",IFERROR(INDEX('Bảng đơn giá'!$D$5:$D$80,MATCH(B21,'Bảng đơn giá'!$C$5:$C$80,0)),"")) | H21: =IF(B21="","",IF(G21<>"",G21,IFERROR(INDEX('Bảng đơn giá'!$E$5:$E$80,MATCH(B21,'Bảng đơn giá'!$C$5:$C$80,0)),0))) | I21: =IF(B21="","",E21*IF(F21="",1,F21)*H21)
A22: =IF(B22="","",COUNTA($B$18:B22)) | D22: =IF(B22="","",IFERROR(INDEX('Bảng đơn giá'!$D$5:$D$80,MATCH(B22,'Bảng đơn giá'!$C$5:$C$80,0)),"")) | H22: =IF(B22="","",IF(G22<>"",G22,IFERROR(INDEX('Bảng đơn giá'!$E$5:$E$80,MATCH(B22,'Bảng đơn giá'!$C$5:$C$80,0)),0))) | I22: =IF(B22="","",E22*IF(F22="",1,F22)*H22)
A23: =IF(B23="","",COUNTA($B$18:B23)) | D23: =IF(B23="","",IFERROR(INDEX('Bảng đơn giá'!$D$5:$D$80,MATCH(B23,'Bảng đơn giá'!$C$5:$C$80,0)),"")) | H23: =IF(B23="","",IF(G23<>"",G23,IFERROR(INDEX('Bảng đơn giá'!$E$5:$E$80,MATCH(B23,'Bảng đơn giá'!$C$5:$C$80,0)),0))) | I23: =IF(B23="","",E23*IF(F23="",1,F23)*H23)
A24: =IF(B24="","",COUNTA($B$18:B24)) | D24: =IF(B24="","",IFERROR(INDEX('Bảng đơn giá'!$D$5:$D$80,MATCH(B24,'Bảng đơn giá'!$C$5:$C$80,0)),"")) | H24: =IF(B24="","",IF(G24<>"",G24,IFERROR(INDEX('Bảng đơn giá'!$E$5:$E$80,MATCH(B24,'Bảng đơn giá'!$C$5:$C$80,0)),0))) | I24: =IF(B24="","",E24*IF(F24="",1,F24)*H24)
A25: =IF(B25="","",COUNTA($B$18:B25)) | D25: =IF(B25="","",IFERROR(INDEX('Bảng đơn giá'!$D$5:$D$80,MATCH(B25,'Bảng đơn giá'!$C$5:$C$80,0)),"")) | H25: =IF(B25="","",IF(G25<>"",G25,IFERROR(INDEX('Bảng đơn giá'!$E$5:$E$80,MATCH(B25,'Bảng đơn giá'!$C$5:$C$80,0)),0))) | I25: =IF(B25="","",E25*IF(F25="",1,F25)*H25)
A26: =IF(B26="","",COUNTA($B$18:B26)) | D26: =IF(B26="","",IFERROR(INDEX('Bảng đơn giá'!$D$5:$D$80,MATCH(B26,'Bảng đơn giá'!$C$5:$C$80,0)),"")) | H26: =IF(B26="","",IF(G26<>"",G26,IFERROR(INDEX('Bảng đơn giá'!$E$5:$E$80,MATCH(B26,'Bảng đơn giá'!$C$5:$C$80,0)),0))) | I26: =IF(B26="","",E26*IF(F26="",1,F26)*H26)
A27: =IF(B27="","",COUNTA($B$18:B27)) | D27: =IF(B27="","",IFERROR(INDEX('Bảng đơn giá'!$D$5:$D$80,MATCH(B27,'Bảng đơn giá'!$C$5:$C$80,0)),"")) | H27: =IF(B27="","",IF(G27<>"",G27,IFERROR(INDEX('Bảng đơn giá'!$E$5:$E$80,MATCH(B27,'Bảng đơn giá'!$C$5:$C$80,0)),0))) | I27: =IF(B27="","",E27*IF(F27="",1,F27)*H27)
A28: =IF(B28="","",COUNTA($B$18:B28)) | D28: =IF(B28="","",IFERROR(INDEX('Bảng đơn giá'!$D$5:$D$80,MATCH(B28,'Bảng đơn giá'!$C$5:$C$80,0)),"")) | H28: =IF(B28="","",IF(G28<>"",G28,IFERROR(INDEX('Bảng đơn giá'!$E$5:$E$80,MATCH(B28,'Bảng đơn giá'!$C$5:$C$80,0)),0))) | I28: =IF(B28="","",E28*IF(F28="",1,F28)*H28)
A29: =IF(B29="","",COUNTA($B$18:B29)) | D29: =IF(B29="","",IFERROR(INDEX('Bảng đơn giá'!$D$5:$D$80,MATCH(B29,'Bảng đơn giá'!$C$5:$C$80,0)),"")) | H29: =IF(B29="","",IF(G29<>"",G29,IFERROR(INDEX('Bảng đơn giá'!$E$5:$E$80,MATCH(B29,'Bảng đơn giá'!$C$5:$C$80,0)),0))) | I29: =IF(B29="","",E29*IF(F29="",1,F29)*H29)
... A37: =IF(B37="","",COUNTA($B$18:B37)) | D37: =IF(B37="","",IFERROR(INDEX('Bảng đơn giá'!$D$5:$D$80,MATCH(B37,'Bảng đơn giá'!$C$5:$C$80,0)),"")) | H37: =IF(B37="","",IF(G37<>"",G37,IFERROR(INDEX('Bảng đơn giá'!$E$5:$E$80,MATCH(B37,'Bảng đơn giá'!$C$5:$C$80,0)),0))) | I37: =IF(B37="","",E37*IF(F37="",1,F37)*H37)
B39: Phí dịch vụ (% trên tạm tính): | C39: 0 | F39: Tạm tính | I39: =SUM(I18:I37) -> 0
B40: Giảm giá (VNĐ): | C40: 0 | F40: Phí dịch vụ | I40: =ROUND(I39*C39,0) -> 0
B41: Thuế VAT (chọn 0% / 8% / 10%): | F41: Giảm giá | I41: =-C40 -> 0
B42: Đặt cọc (% tổng cộng): | F42: Tổng trước thuế | I42: =I39+I40+I41 -> 0
F43: Thuế VAT | I43: =ROUND(I42*N(C41),0) -> 0
F44: TỔNG CỘNG | I44: =I42+I43 -> 0
F45: Giá trung bình / khách | I45: =IF(N($H$13)=0,"",ROUND(I44/$H$13,0))
F46: Đặt cọc | I46: =ROUND(I44*N(C42),0) -> 0
F47: Còn lại | I47: =I44-I46 -> 0
A49: ĐIỀU KHOẢN
A50: Giá đã bao gồm: | C50: [Điền: các hạng mục trong bảng trên, bảo hiểm, HDV…]
A51: Giá chưa bao gồm: | C51: [Điền: chi tiêu cá nhân, đồ uống ngoài chương trình…]
A52: Thanh toán: | C52: [Điền: tỉ lệ cọc khi ký hợp đồng, hạn thanh toán phần còn lại, chuyển khoản]
A53: Huỷ / đổi: | C53: [Điền: chính sách huỷ, đổi ngày theo từng mốc thời gian]
...

Sheet Bảng đơn giá
A1: BẢNG ĐƠN GIÁ THAM KHẢO — sales điền giá thật vào cột E (nền vàng)
A2: Hạng mục chọn ở sheet Báo giá sẽ tự lấy đơn vị + đơn giá ở đây. Thêm hạng mục mới: ghi tiếp vào dòng trống bên dưới (tối đa dòng 80).
A4: Mã | B4: Nhóm | C4: Hạng mục | D4: Đơn vị | E4: Đơn giá (VNĐ) | F4: Ghi chú (nhà cung cấp, mùa, cập nhật ngày)
A5: M01 | B5: Vận chuyển | C5: Xe 16 chỗ | D5: xe/ngày
A6: M02 | B6: Vận chuyển | C6: Xe 29 chỗ | D6: xe/ngày
A7: M03 | B7: Vận chuyển | C7: Xe 35 chỗ | D7: xe/ngày
A8: M04 | B8: Vận chuyển | C8: Xe 45 chỗ | D8: xe/ngày
A9: M05 | B9: Vận chuyển | C9: Vé máy bay khứ hồi | D9: khách
A10: M06 | B10: Vận chuyển | C10: Tàu / cano | D10: khách
A11: M07 | B11: Lưu trú | C11: Khách sạn 3 sao (phòng đôi) | D11: phòng/đêm
A12: M08 | B12: Lưu trú | C12: Khách sạn 4 sao (phòng đôi) | D12: phòng/đêm
A13: M09 | B13: Lưu trú | C13: Khách sạn 5 sao (phòng đôi) | D13: phòng/đêm
A14: M10 | B14: Lưu trú | C14: Resort (phòng đôi) | D14: phòng/đêm
A15: M11 | B15: Ăn uống | C15: Ăn sáng | D15: khách/bữa
A16: M12 | B16: Ăn uống | C16: Ăn chính | D16: khách/bữa
... A33: M29 | B33: Khác | C33: Quà tặng | D33: phần
A34: M30
A35: M31
A36: M32
A37: M33
A38: M34
A39: M35
A40: M36
A41: M37
A42: M38
A43: M39
A44: M40
A45: M41
... A80: M76

Sheet Hướng dẫn
A1: MẪU BÁO GIÁ NHANH CHO DOANH NGHIỆP — CÁCH DÙNG
A3: Chỉ điền các ô NỀN VÀNG, chữ xanh. Ô trắng là công thức, tự tính — không gõ đè.
A4: 1. Lần đầu: sang sheet "Bảng đơn giá", điền đơn giá thật vào cột E (giá đang để trống vì mỗi mùa, mỗi nhà cung cấp một khác).
A5: 2. Mỗi báo giá: chép sheet "Báo giá" (chuột phải → Move or Copy → Create a copy), đặt tên theo khách.
A6: 3. Điền thông tin khách, SỐ KHÁCH (để tính giá / khách), rồi chọn hạng mục ở cột B — đơn vị và đơn giá tự lấy từ bảng giá.
A7: Giá lần này khác bảng giá: gõ vào cột "Đơn giá nhập tay". Hạng mục không có trong bảng: gõ tên + nhập tay đơn giá.
A8: Ô "Đơn giá áp dụng" tô cam = đã chọn hạng mục nhưng chưa có giá.
A9: 4. Số ngày / lần để trống = 1. VD xe 29 chỗ × 2 xe × 3 ngày: Số lượng 2, Số ngày 3.
A10: 5. Chọn mức VAT (ô tô cam khi chưa chọn), % đặt cọc, phí dịch vụ nếu có. Điền phần Điều khoản trước khi gửi.
A11: 6. In / xuất PDF: File → Print (khổ A4 dọc, đã căn sẵn vừa trang).
A13: VÍ DỤ (số minh hoạ, KHÔNG phải giá thật của PSV):
A14: Hạng mục | B14: Diễn giải | C14: Đơn vị | D14: Số lượng | E14: Số ngày / lần | F14: Đơn giá | G14: Thành tiền
A15: Xe 29 chỗ | B15: Đưa đón TP.HCM – Phan Thiết | C15: xe/ngày | D15: 2 | E15: 3 | F15: 2500000 | G15: =D15*E15*F15 -> 15000000
A16: Resort (phòng đôi) | B16: 2 khách / phòng | C16: phòng/đêm | D16: 25 | E16: 2 | F16: 1800000 | G16: =D16*E16*F16 -> 90000000
