Workbook

Sheet Hướng dẫn
A1: Theo dõi PSV Travel trên trợ lý AI (ChatGPT, Perplexity, Gemini, Google AI Overview, Copilot)
A3: Mục đích: mỗi tháng biết PSV có được AI nhắc tới / gợi ý / dẫn link khi khách hỏi những câu có thể ra đơn.
A5: CÁCH LÀM MỖI THÁNG (khoảng 1 buổi):
A6: 1. Mở cửa sổ ẩn danh hoặc đăng xuất (tránh AI nhớ lịch sử của bạn). Đặt vị trí Việt Nam nếu được hỏi.
A7: 2. Với mỗi câu ở sheet "Câu hỏi" thuộc nhóm Cốt lõi + Đối chứng: hỏi 3 LẦN trên mỗi nền tảng, mỗi lần một cuộc trò chuyện MỚI.
A8: AI trả lời mỗi lần một khác — 1 lần hỏi chưa nói lên gì; 3 lần cho ra tỉ lệ (VD: được nhắc 2/3).
A9: 3. Mỗi lần hỏi = 1 dòng ở sheet "Theo dõi". Chỉ điền các ô nền vàng; ô "Câu hỏi" tự hiện theo mã.
A10: 4. Sheet "Tổng hợp" tự tính tỉ lệ theo tháng và nền tảng. So tháng này với tháng trước, không so từng lần hỏi.
A11: 5. Nhóm Thăm dò: thử khi có thời gian; câu nào hay thì chuyển lên Cốt lõi và ghi ngày đổi vào cột Ghi chú.
A13: ĐIỀN THẾ NÀO:
A14: - Được nhắc: câu trả lời có tên PSV Travel / P.S.V Travel / psvtravel.com ở bất kỳ đâu.
A15: - Được gợi ý: PSV nằm trong danh sách công ty AI khuyên chọn (không chỉ nhắc qua).
... A24: VÍ DỤ MỘT DÒNG Ở SHEET "Theo dõi":
A25: Tháng | B25: Mã câu hỏi | C25: Câu hỏi (tự hiện) | D25: Nền tảng | E25: Lần hỏi | F25: Được nhắc? | G25: Được gợi ý? | H25: Có link? | I25: Trang PSV được dẫn | J25: Đối thủ được nhắc | K25: Nguồn AI dẫn | L25: Thông tin sai về PSV | M25: Ghi chú
A26: 2026-11 | B26: Q02 | C26: Nên đặt tour Trung Quốc No Shopping ở công ty nào tại TP.HCM? | D26: Perplexity | E26: 1 | F26: Không | G26: Không | H26: Không | J26: Vietravel, Saigontourist | K26: vietnambooking.com, yellowpages.vn | M26: Ví dụ — không tính vào thống kê

Sheet Câu hỏi
A1: Mã | B1: Nhóm | C1: Loại | D1: Câu hỏi (hỏi đúng nguyên văn) | E1: Trang PSV nên được dẫn | F1: Ghi chú
A2: Q01 | B2: Tìm công ty | C2: Cốt lõi | D2: Công ty du lịch nào uy tín ở TP.HCM để đặt tour nước ngoài trọn gói? | E2: https://psvtravel.com/
A3: Q02 | B3: Gợi ý theo nhu cầu | C3: Cốt lõi | D3: Nên đặt tour Trung Quốc No Shopping ở công ty nào tại TP.HCM? | E3: https://psvtravel.com/tour-nuoc-ngoai | F3: Tour No Shopping của PSV
A4: Q03 | B4: Giá | C4: Cốt lõi | D4: Tour Hàn Quốc 5 ngày 4 đêm khởi hành từ TP.HCM giá bao nhiêu, công ty nào tổ chức? | E4: https://psvtravel.com/pricing.md
A5: Q04 | B5: Giá | C5: Cốt lõi | D5: Tour Bắc Kinh – Thượng Hải 6 ngày bay thẳng từ TP.HCM giá khoảng bao nhiêu? | E5: Trang tour Bắc Kinh – Thượng Hải | F5: Tuyến đang chạy banner
A6: Q05 | B6: Tìm công ty | C6: Cốt lõi | D6: Công ty nào ở TP.HCM tổ chức du lịch công ty, team building trọn gói cho doanh nghiệp? | E6: https://psvtravel.com/team-building | F6: Khách B2B
A7: Q06 | B7: Dịch vụ | C7: Cốt lõi | D7: Làm visa Hàn Quốc trọn gói ở TP.HCM, phí dịch vụ bao nhiêu và mất bao lâu? | E7: https://psvtravel.com/lam-visa
A8: Q07 | B8: Mùa vụ | C8: Cốt lõi | D8: Tour Tết 2027 đi nước ngoài khởi hành từ TP.HCM nên đặt ở đâu, đặt trước bao lâu? | E8: https://psvtravel.com/tour-tet | F8: Đổi năm mỗi mùa Tết
A9: Q08 | B9: Gợi ý theo nhu cầu | C9: Cốt lõi | D9: Tour Phú Quốc hoặc Đà Lạt trọn gói cho gia đình từ TP.HCM, công ty nào tốt? | E9: https://psvtravel.com/tour-trong-nuoc
A10: Q09 | B10: Địa phương | C10: Cốt lõi | D10: Công ty lữ hành có giấy phép lữ hành quốc tế ở Quận 7 / Tân Thuận, TP.HCM? | E10: https://psvtravel.com/lien-he
A11: Q10 | B11: Uy tín | C11: Cốt lõi | D11: PSV Travel có uy tín không? Có giấy phép lữ hành quốc tế không? | E11: https://psvtravel.com/ve-chung-toi | F11: Câu thương hiệu
A12: Q11 | B12: Giá | C12: Cốt lõi | D12: Giá tour của PSV Travel đã bao gồm những gì, có phụ thu không? | E12: Trang tour bất kỳ
A13: Q12 | B13: So sánh | C13: Cốt lõi | D13: Nên đặt tour Hàn Quốc ở PSV Travel, Vietravel hay Saigontourist? | E13: Trang tour Hàn Quốc
A14: Q13 | B14: Kinh nghiệm | C14: Thăm dò | D14: Làm sao chọn tour Trung Quốc No Shopping để không bị ép mua sắm? | E14: Bài cẩm nang (nếu có) | F14: Nên có bài cẩm nang trả lời câu này
A15: Q14 | B15: Kinh nghiệm | C15: Thăm dò | D15: Đi Hàn Quốc theo tour cần giấy tờ visa gì, nộp hồ sơ trước bao lâu? | E15: https://psvtravel.com/lam-visa
A16: Q15 | B16: Giá | C16: Thăm dò | D16: Company trip 3 ngày 2 đêm cho 50 người đi Phan Thiết chi phí khoảng bao nhiêu? | E16: https://psvtravel.com/team-building
A17: Q16 | B17: Gợi ý theo nhu cầu | C17: Thăm dò | D17: Tour Nhật Bản mùa thu ngắm lá đỏ khởi hành từ Sài Gòn, công ty nào có tour? | E17: https://psvtravel.com/tour-nuoc-ngoai
A18: Q17 | B18: So sánh | C18: Thăm dò | D18: Đi tour hay tự túc khi du lịch Trung Quốc lần đầu? | E18: Bài cẩm nang (nếu có)
A19: Q18 | B19: Đối chứng | C19: Đối chứng | D19: PSV Travel ở đâu, hotline bao nhiêu? | E19: https://psvtravel.com/lien-he | F19: LUÔN phải có PSV. Không có = AI chưa biết PSV
A20: Q19 | B20: Đối chứng | C20: Đối chứng | D20: psvtravel.com là website của công ty nào? | E20: https://psvtravel.com/ | F20: LUÔN phải có PSV
A21: Q20 | B21: Đối chứng | C21: Đối chứng | D21: Cách nấu phở bò ngon tại nhà? | E21: (không liên quan) | F21: KHÔNG BAO GIỜ có PSV. Có = đo sai
A23: Phiên bản bộ câu hỏi: 1.0 (22/10/2026). Đổi câu hỏi Cốt lõi thì ghi ngày + lý do vào Ghi chú — không so tháng dùng bộ câu khác nhau.

Sheet Theo dõi
A1: Tháng | B1: Mã câu hỏi | C1: Câu hỏi (tự hiện) | D1: Nền tảng | E1: Lần hỏi | F1: Được nhắc? | G1: Được gợi ý? | H1: Có link? | I1: Trang PSV được dẫn | J1: Đối thủ được nhắc | K1: Nguồn AI dẫn | L1: Thông tin sai về PSV | M1: Ghi chú
C2: =IF(B2="","",IFERROR(INDEX('Câu hỏi'!$D$2:$D$21,MATCH(B2,'Câu hỏi'!$A$2:$A$21,0)),"Mã không có"))
C3: =IF(B3="","",IFERROR(INDEX('Câu hỏi'!$D$2:$D$21,MATCH(B3,'Câu hỏi'!$A$2:$A$21,0)),"Mã không có"))
C4: =IF(B4="","",IFERROR(INDEX('Câu hỏi'!$D$2:$D$21,MATCH(B4,'Câu hỏi'!$A$2:$A$21,0)),"Mã không có"))
C5: =IF(B5="","",IFERROR(INDEX('Câu hỏi'!$D$2:$D$21,MATCH(B5,'Câu hỏi'!$A$2:$A$21,0)),"Mã không có"))
C6: =IF(B6="","",IFERROR(INDEX('Câu hỏi'!$D$2:$D$21,MATCH(B6,'Câu hỏi'!$A$2:$A$21,0)),"Mã không có"))
C7: =IF(B7="","",IFERROR(INDEX('Câu hỏi'!$D$2:$D$21,MATCH(B7,'Câu hỏi'!$A$2:$A$21,0)),"Mã không có"))
C8: =IF(B8="","",IFERROR(INDEX('Câu hỏi'!$D$2:$D$21,MATCH(B8,'Câu hỏi'!$A$2:$A$21,0)),"Mã không có"))
C9: =IF(B9="","",IFERROR(INDEX('Câu hỏi'!$D$2:$D$21,MATCH(B9,'Câu hỏi'!$A$2:$A$21,0)),"Mã không có"))
C10: =IF(B10="","",IFERROR(INDEX('Câu hỏi'!$D$2:$D$21,MATCH(B10,'Câu hỏi'!$A$2:$A$21,0)),"Mã không có"))
C11: =IF(B11="","",IFERROR(INDEX('Câu hỏi'!$D$2:$D$21,MATCH(B11,'Câu hỏi'!$A$2:$A$21,0)),"Mã không có"))
C12: =IF(B12="","",IFERROR(INDEX('Câu hỏi'!$D$2:$D$21,MATCH(B12,'Câu hỏi'!$A$2:$A$21,0)),"Mã không có"))
C13: =IF(B13="","",IFERROR(INDEX('Câu hỏi'!$D$2:$D$21,MATCH(B13,'Câu hỏi'!$A$2:$A$21,0)),"Mã không có"))
... C601: =IF(B601="","",IFERROR(INDEX('Câu hỏi'!$D$2:$D$21,MATCH(B601,'Câu hỏi'!$A$2:$A$21,0)),"Mã không có"))

Sheet Tổng hợp
A1: Tỉ lệ PSV được nhắc / gợi ý / có link — theo tháng và nền tảng
A2: Tự tính từ sheet Theo dõi. Tỉ lệ = số lần có / số lần hỏi. Ô trống = tháng đó chưa hỏi nền tảng này. Câu Đối chứng (Q18–Q20) không tính vào tỉ lệ.
A4: Được nhắc — tỉ lệ
A5: Tháng | B5: Số lần hỏi (mọi nền tảng) | C5: ChatGPT | D5: Perplexity | E5: Gemini | F5: Google AI Overview | G5: Copilot | H5: Tất cả
A6: 2026-10 | B6: =COUNTIFS('Theo dõi'!$A$2:$A$601,$A6,'Theo dõi'!$D$2:$D$601,"<>")-COUNTIFS('Theo dõi'!$A$2:$A$601,$A6,'Theo dõi'!$D$2:$D$601,"<>",'Theo dõi'!$B$2:$B$601,"Q18")-COUNTIFS('Theo dõi'!$A$2:$A$601,$A6,'Theo dõi'!$D$2:$D$601,"<>",'Theo dõi'!$B$2:$B$601,"Q19")-COUNTIFS('Theo dõi'!$A$2:$A$601,$A6,'Theo dõi'!$D$2:$D$601,"<>",'Theo dõi'!$B$2:$B$601,"Q20") -> 0 | C6: =IF((COUNTIFS('Theo dõi'!$A$2:$A$601,$A6,'Theo dõi'!$D$2:$D$601,"ChatGPT")-COUNTIFS('Theo dõi'!$A$2:$A$601,$A6,'Theo dõi'!$D$2:$D$601,"ChatGPT",'Theo dõi'!$B$2:$B$601,"Q18")-COUNTIFS('Theo dõi'!$A$2:$A$601,$A6,'Theo dõi'!$D$2:$D$601,"ChatGPT",'Theo dõi'!$B$2:$B$601,"Q19")-COUNTIFS('Theo dõi'!$A$2:$A$601,$A6,'Theo dõi'!$D$2:$D$601,"ChatGPT",'Theo dõi'!$B$2:$B$601,"Q20"))=0,"",(COUNTIFS('Theo dõi'!$A$2:$A$601,$A6,'Theo dõi'!$D$2:$D$601,"ChatGPT",'Theo dõi'!$F$2:$F$601,"Có")-COUNTIFS('Theo dõi'!$A$2:$A$601,$A6,'Theo dõi'!$D$2:$D$601,"ChatGPT",'Theo dõi'!$F$2:$F$601,"Có",'Theo dõi'!$B$2:$B$601,"Q18")-COUNTIFS('Theo dõi'!$A$2:$A$601,$A6,'Theo dõi'!$D$2:$D$601,"ChatGPT",'Theo dõi'!$F$2:$F$601,"Có",'Theo dõi'!$B$2:$B$601,"Q19")-COUNTIFS('Theo dõi'!$A$2:$A$601,$A6,'Theo dõi'!$D$2:$D$601,"ChatGPT",'Theo dõi'!$F$2:$F$601,"Có",'Theo dõi'!$B$2:$B$601,"Q20"))/(COUNTIFS('Theo dõi'!$A$2:$A$601,$A6,'Theo dõi'!$D$2:$D$601,"ChatGPT")-COUNTIFS('Theo dõi'!$A$2:$A$601,$A6,'Theo dõi'!$D$2:$D$601,"ChatGPT",'Theo dõi'!$B$2:$B$601,"Q18")-COUNTIFS('Theo dõi'!$A$2:$A$601,$A6,'Theo dõi'!$D$2:$D$601,"ChatGPT",'Theo dõi'!$B$2:$B$601,"Q19")-COUNTIFS('Theo dõi'!$A$2:$A$601,$A6,'Theo dõi'!$D$2:$D$601,"ChatGPT",'Theo dõi'!$B$2:$B$601,"Q20"))) | D6: =IF((COUNTIFS('Theo dõi'!$A$2:$A$601,$A6,'Theo dõi'!$D$2:$D$601,"Perplexity")-COUNTIFS('Theo dõi'!$A$2:$A$601,$A6,'Theo dõi'!$D$2:$D$601,"Perplexity",'Theo dõi'!$B$2:$B$601,"Q18")-COUNTIFS('Theo dõi'!$A$2:$A$601,$A6,'Theo dõi'!$D$2:$D$601,"Perplexity",'Theo dõi'!$B$2:$B$601,"Q19")-COUNTIFS('Theo dõi'!$A$2:$A$601,$A6,'Theo dõi'!$D$2:$D$601,"Perplexity",'Theo dõi'!$B$2:$B$601,"Q20"))=0,"",(COUNTIFS('Theo dõi'!$A$2:$A$601,$A6,'Theo dõi'!$D$2:$D$601,"Perplexity",'Theo dõi'!$F$2:$F$601,"Có")-COUNTIFS('Theo dõi'!$A$2:$A$601,$A6,'Theo dõi'!$D$2:$D$601,"Perplexity",'Theo dõi'!$F$2:$F$601,"Có",'Theo dõi'!$B$2:$B$601,"Q18")-COUNTIFS('Theo dõi'!$A$2:$A$601,$A6,'Theo dõi'!$D$2:$D$601,"Perplexity",'Theo dõi'!$F$2:$F$601,"Có",'Theo dõi'!$B$2:$B$601,"Q19")-COUNTIFS('Theo dõi'!$A$2:$A$601,$A6,'Theo dõi'!$D$2:$D$601,"Perplexity",'Theo dõi'!$F$2:$F$601,"Có",'Theo dõi'!$B$2:$B$601,"Q20"))/(COUNTIFS('Theo dõi'!$A$2:$A$601,$A6,'Theo dõi'!$D$2:$D$601,"Perplexity")-COUNTIFS('Theo dõi'!$A$2:$A$601,$A6,'Theo dõi'!$D$2:$D$601,"Perplexity",'Theo dõi'!$B$2:$B$601,"Q18")-COUNTIFS('Theo dõi'!$A$2:$A$601,$A6,'Theo dõi'!$D$2:$D$601,"Perplexity",'Theo dõi'!$B$2:$B$601,"Q19")-COUNTIFS('Theo dõi'!$A$2:$A$601,$A6,'Theo dõi'!$D$2:$D$601,"Perplexity",'Theo dõi'!$B$2:$B$601,"Q20"))) | E6: =IF((COUNTIFS('Theo dõi'!$A$2:$A$601,$A6,'Theo dõi'!$D$2:$D$601,"Gemini")-COUNTIFS('Theo dõi'!$A$2:$A$601,$A6,'Theo dõi'!$D$2:$D$601,"Gemini",'Theo dõi'!$B$2:$B$601,"Q18")-COUNTIFS('Theo dõi'!$A$2:$A$601,$A6,'Theo dõi'!$D$2:$D$601,"Gemini",'Theo dõi'!$B$2:$B$601,"Q19")-COUNTIFS('Theo dõi'!$A$2:$A$601,$A6,'Theo dõi'!$D$2:$D$601,"Gemini",'Theo dõi'!$B$2:$B$601,"Q20"))=0,"",(COUNTIFS('Theo dõi'!$A$2:$A$601,$A6,'Theo dõi'!$D$2:$D$601,"Gemini",'Theo dõi'!$F$2:$F$601,"Có")-COUNTIFS('Theo dõi'!$A$2:$A$601,$A6,'Theo dõi'!$D$2:$D$601,"Gemini",'Theo dõi'!$F$2:$F$601,"Có",'Theo dõi'!$B$2:$B$601,"Q18")-COUNTIFS('Theo dõi'!$A$2:$A$601,$A6,'Theo dõi'!$D$2:$D$601,"Gemini",'Theo dõi'!$F$2:$F$601,"Có",'Theo dõi'!$B$2:$B$601,"Q19")-COUNTIFS('Theo dõi'!$A$2:$A$601,$A6,'Theo dõi'!$D$2:$D$601,"Gemini",'Theo dõi'!$F$2:$F$601,"Có",'Theo dõi'!$B$2:$B$601,"Q20"))/(COUNTIFS('Theo dõi'!$A$2:$A$601,$A6,'Theo dõi'!$D$2:$D$601,"Gemini")-COUNTIFS('Theo dõi'!$A$2:$A$601,$A6,'Theo dõi'!$D$2:$D$601,"Gemini",'Theo dõi'!$B$2:$B$601,"Q18")-COUNTIFS('Theo dõi'!$A$2:$A$601,$A6,'Theo dõi'!$D$2:$D$601,"Gemini",'Theo dõi'!$B$2:$B$601,"Q19")-COUNTIFS('Theo dõi'!$A$2:$A$601,$A6,'Theo dõi'!$D$2:$D$601,"Gemini",'Theo dõi'!$B$2:$B$601,"Q20"))) | F6: =IF((COUNTIFS('Theo dõi'!$A$2:$A$601,$A6,'Theo dõi'!$D$2:$D$601,"Google AI Overview")-COUNTIFS('Theo dõi'!$A$2:$A$601,$A6,'Theo dõi'!$D$2:$D$601,"Google AI Overview",'Theo dõi'!$B$2:$B$601,"Q18")-COUNTIFS('Theo dõi'!$A$2:$A$601,$A6,'Theo dõi'!$D$2:$D$601,"Google AI Overview",'Theo dõi'!$B$2:$B$601,"Q19")-COUNTIFS('Theo dõi'!$A$2:$A$601,$A6,'Theo dõi'!$D$2:$D$601,"Google AI Overview",'Theo dõi'!$B$2:$B$601,"Q20"))=0,"",(COUNTIFS('Theo dõi'!$A$2:$A$601,$A6,'Theo dõi'!$D$2:$D$601,"Google AI Overview",'Theo dõi'!$F$2:$F$601,"Có")-COUNTIFS('Theo dõi'!$A$2:$A$601,$A6,'Theo dõi'!$D$2:$D$601,"Google AI Overview",'Theo dõi'!$F$2:$F$601,"Có",'Theo dõi'!$B$2:$B$601,"Q18")-COUNTIFS('Theo dõi'!$A$2:$A$601,$A6,'Theo dõi'!$D$2:$D$601,"Google AI Overview",'Theo dõi'!$F$2:$F$601,"Có",'Theo dõi'!$B$2:$B$601,"Q19")-COUNTIFS('Theo dõi'!$A$2:$A$601,$A6,'Theo dõi'!$D$2:$D$601,"Google AI Overview",'Theo dõi'!$F$2:$F$601,"Có",'Theo dõi'!$B$2:$B$601,"Q20"))/(COUNTIFS('Theo dõi'!$A$2:$A$601,$A6,'Theo dõi'!$D$2:$D$601,"Google AI Overview")-COUNTIFS('Theo dõi'!$A$2:$A$601,$A6,'Theo dõi'!$D$2:$D$601,"Google AI Overview",'Theo dõi'!$B$2:$B$601,"Q18")-COUNTIFS('Theo dõi'!$A$2:$A$601,$A6,'Theo dõi'!$D$2:$D$601,"Google AI Overview",'Theo dõi'!$B$2:$B$601,"Q19")-COUNTIFS('Theo dõi'!$A$2:$A$601,$A6,'Theo dõi'!$D$2:$D$601,"Google AI Overview",'Theo dõi'!$B$2:$B$601,"Q20"))) | G6: =IF((COUNTIFS('Theo dõi'!$A$2:$A$601,$A6,'Theo dõi'!$D$2:$D$601,"Copilot")-COUNTIFS('Theo dõi'!$A$2:$A$601,$A6,'Theo dõi'!$D$2:$D$601,"Copilot",'Theo dõi'!$B$2:$B$601,"Q18")-COUNTIFS('Theo dõi'!$A$2:$A$601,$A6,'Theo dõi'!$D$2:$D$601,"Copilot",'Theo dõi'!$B$2:$B$601,"Q19")-COUNTIFS('Theo dõi'!$A$2:$A$601,$A6,'Theo dõi'!$D$2:$D$601,"Copilot",'Theo dõi'!$B$2:$B$601,"Q20"))=0,"",(COUNTIFS('Theo dõi'!$A$2:$A$601,$A6,'Theo dõi'!$D$2:$D$601,"Copilot",'Theo dõi'!$F$2:$F$601,"Có")-COUNTIFS('Theo dõi'!$A$2:$A$601,$A6,'Theo dõi'!$D$2:$D$601,"Copilot",'Theo dõi'!$F$2:$F$601,"Có",'Theo dõi'!$B$2:$B$601,"Q18")-COUNTIFS('Theo dõi'!$A$2:$A$601,$A6,'Theo dõi'!$D$2:$D$601,"Copilot",'Theo dõi'!$F$2:$F$601,"Có",'Theo dõi'!$B$2:$B$601,"Q19")-COUNTIFS('Theo dõi'!$A$2:$A$601,$A6,'Theo dõi'!$D$2:$D$601,"Copilot",'Theo dõi'!$F$2:$F$601,"Có",'Theo dõi'!$B$2:$B$601,"Q20"))/(COUNTIFS('Theo dõi'!$A$2:$A$601,$A6,'Theo dõi'!$D$2:$D$601,"Copilot")-COUNTIFS('Theo dõi'!$A$2:$A$601,$A6,'Theo dõi'!$D$2:$D$601,"Copilot",'Theo dõi'!$B$2:$B$601,"Q18")-COUNTIFS('Theo dõi'!$A$2:$A$601,$A6,'Theo dõi'!$D$2:$D$601,"Copilot",'Theo dõi'!$B$2:$B$601,"Q19")-COUNTIFS('Theo dõi'!$A$2:$A$601,$A6,'Theo dõi'!$D$2:$D$601,"Copilot",'Theo dõi'!$B$2:$B$601,"Q20"))) | H6: =IF((COUNTIFS('Theo dõi'!$A$2:$A$601,$A6,'Theo dõi'!$D$2:$D$601,"<>")-COUNTIFS('Theo dõi'!$A$2:$A$601,$A6,'Theo dõi'!$D$2:$D$601,"<>",'Theo dõi'!$B$2:$B$601,"Q18")-COUNTIFS('Theo dõi'!$A$2:$A$601,$A6,'Theo dõi'!$D$2:$D$601,"<>",'Theo dõi'!$B$2:$B$601,"Q19")-COUNTIFS('Theo dõi'!$A$2:$A$601,$A6,'Theo dõi'!$D$2:$D$601,"<>",'Theo dõi'!$B$2:$B$601,"Q20"))=0,"",(COUNTIFS('Theo dõi'!$A$2:$A$601,$A6,'Theo dõi'!$D$2:$D$601,"<>",'Theo dõi'!$F$2:$F$601,"Có")-COUNTIFS('Theo dõi'!$A$2:$A$601,$A6,'Theo dõi'!$D$2:$D$601,"<>",'Theo dõi'!$F$2:$F$601,"Có",'Theo dõi'!$B$2:$B$601,"Q18")-COUNTIFS('Theo dõi'!$A$2:$A$601,$A6,'Theo dõi'!$D$2:$D$601,"<>",'Theo dõi'!$F$2:$F$601,"Có",'Theo dõi'!$B$2:$B$601,"Q19")-COUNTIFS('Theo dõi'!$A$2:$A$601,$A6,'Theo dõi'!$D$2:$D$601,"<>",'Theo dõi'!$F$2:$F$601,"Có",'Theo dõi'!$B$2:$B$601,"Q20"))/(COUNTIFS('Theo dõi'!$A$2:$A$601,$A6,'Theo dõi'!$D$2:$D$601,"<>")-COUNTIFS('Theo dõi'!$A$2:$A$601,$A6,'Theo dõi'!$D$2:$D$601,"<>",'Theo dõi'!$B$2:$B$601,"Q18")-COUNTIFS('Theo dõi'!$A$2:$A$601,$A6,'Theo dõi'!$D$2:$D$601,"<>",'Theo dõi'!$B$2:$B$601,"Q19")-COUNTIFS('Theo dõi'!$A$2:$A$601,$A6,'Theo dõi'!$D$2:$D$601,"<>",'Theo dõi'!$B$2:$B$601,"Q20")))
A7: 2026-11 | B7: =COUNTIFS('Theo dõi'!$A$2:$A$601,$A7,'Theo dõi'!$D$2:$D$601,"<>")-COUNTIFS('Theo dõi'!$A$2:$A$601,$A7,'Theo dõi'!$D$2:$D$601,"<>",'Theo dõi'!$B$2:$B$601,"Q18")-COUNTIFS('Theo dõi'!$A$2:$A$601,$A7,'Theo dõi'!$D$2:$D$601,"<>",'Theo dõi'!$B$2:$B$601,"Q19")-COUNTIFS('Theo dõi'!$A$2:$A$601,$A7,'Theo dõi'!$D$2:$D$601,"<>",'Theo dõi'!$B$2:$B$601,"Q20") -> 0 | C7: =IF((COUNTIFS('Theo dõi'!$A$2:$A$601,$A7,'Theo dõi'!$D$2:$D$601,"ChatGPT")-COUNTIFS('Theo dõi'!$A$2:$A$601,$A7,'Theo dõi'!$D$2:$D$601,"ChatGPT",'Theo dõi'!$B$2:$B$601,"Q18")-COUNTIFS('Theo dõi'!$A$2:$A$601,$A7,'Theo dõi'!$D$2:$D$601,"ChatGPT",'Theo dõi'!$B$2:$B$601,"Q19")-COUNTIFS('Theo dõi'!$A$2:$A$601,$A7,'Theo dõi'!$D$2:$D$601,"ChatGPT",'Theo dõi'!$B$2:$B$601,"Q20"))=0,"",(COUNTIFS('Theo dõi'!$A$2:$A$601,$A7,'Theo dõi'!$D$2:$D$601,"ChatGPT",'Theo dõi'!$F$2:$F$601,"Có")-COUNTIFS('Theo dõi'!$A$2:$A$601,$A7,'Theo dõi'!$D$2:$D$601,"ChatGPT",'Theo dõi'!$F$2:$F$601,"Có",'Theo dõi'!$B$2:$B$601,"Q18")-COUNTIFS('Theo dõi'!$A$2:$A$601,$A7,'Theo dõi'!$D$2:$D$601,"ChatGPT",'Theo dõi'!$F$2:$F$601,"Có",'Theo dõi'!$B$2:$B$601,"Q19")-COUNTIFS('Theo dõi'!$A$2:$A$601,$A7,'Theo dõi'!$D$2:$D$601,"ChatGPT",'Theo dõi'!$F$2:$F$601,"Có",'Theo dõi'!$B$2:$B$601,"Q20"))/(COUNTIFS('Theo dõi'!$A$2:$A$601,$A7,'Theo dõi'!$D$2:$D$601,"ChatGPT")-COUNTIFS('Theo dõi'!$A$2:$A$601,$A7,'Theo dõi'!$D$2:$D$601,"ChatGPT",'Theo dõi'!$B$2:$B$601,"Q18")-COUNTIFS('Theo dõi'!$A$2:$A$601,$A7,'Theo dõi'!$D$2:$D$601,"ChatGPT",'Theo dõi'!$B$2:$B$601,"Q19")-COUNTIFS('Theo dõi'!$A$2:$A$601,$A7,'Theo dõi'!$D$2:$D$601,"ChatGPT",'Theo dõi'!$B$2:$B$601,"Q20"))) | D7: =IF((COUNTIFS('Theo dõi'!$A$2:$A$601,$A7,'Theo dõi'!$D$2:$D$601,"Perplexity")-COUNTIFS('Theo dõi'!$A$2:$A$601,$A7,'Theo dõi'!$D$2:$D$601,"Perplexity",'Theo dõi'!$B$2:$B$601,"Q18")-COUNTIFS('Theo dõi'!$A$2:$A$601,$A7,'Theo dõi'!$D$2:$D$601,"Perplexity",'Theo dõi'!$B$2:$B$601,"Q19")-COUNTIFS('Theo dõi'!$A$2:$A$601,$A7,'Theo dõi'!$D$2:$D$601,"Perplexity",'Theo dõi'!$B$2:$B$601,"Q20"))=0,"",(COUNTIFS('Theo dõi'!$A$2:$A$601,$A7,'Theo dõi'!$D$2:$D$601,"Perplexity",'Theo dõi'!$F$2:$F$601,"Có")-COUNTIFS('Theo dõi'!$A$2:$A$601,$A7,'Theo dõi'!$D$2:$D$601,"Perplexity",'Theo dõi'!$F$2:$F$601,"Có",'Theo dõi'!$B$2:$B$601,"Q18")-COUNTIFS('Theo dõi'!$A$2:$A$601,$A7,'Theo dõi'!$D$2:$D$601,"Perplexity",'Theo dõi'!$F$2:$F$601,"Có",'Theo dõi'!$B$2:$B$601,"Q19")-COUNTIFS('Theo dõi'!$A$2:$A$601,$A7,'Theo dõi'!$D$2:$D$601,"Perplexity",'Theo dõi'!$F$2:$F$601,"Có",'Theo dõi'!$B$2:$B$601,"Q20"))/(COUNTIFS('Theo dõi'!$A$2:$A$601,$A7,'Theo dõi'!$D$2:$D$601,"Perplexity")-COUNTIFS('Theo dõi'!$A$2:$A$601,$A7,'Theo dõi'!$D$2:$D$601,"Perplexity",'Theo dõi'!$B$2:$B$601,"Q18")-COUNTIFS('Theo dõi'!$A$2:$A$601,$A7,'Theo dõi'!$D$2:$D$601,"Perplexity",'Theo dõi'!$B$2:$B$601,"Q19")-COUNTIFS('Theo dõi'!$A$2:$A$601,$A7,'Theo dõi'!$D$2:$D$601,"Perplexity",'Theo dõi'!$B$2:$B$601,"Q20"))) | E7: =IF((COUNTIFS('Theo dõi'!$A$2:$A$601,$A7,'Theo dõi'!$D$2:$D$601,"Gemini")-COUNTIFS('Theo dõi'!$A$2:$A$601,$A7,'Theo dõi'!$D$2:$D$601,"Gemini",'Theo dõi'!$B$2:$B$601,"Q18")-COUNTIFS('Theo dõi'!$A$2:$A$601,$A7,'Theo dõi'!$D$2:$D$601,"Gemini",'Theo dõi'!$B$2:$B$601,"Q19")-COUNTIFS('Theo dõi'!$A$2:$A$601,$A7,'Theo dõi'!$D$2:$D$601,"Gemini",'Theo dõi'!$B$2:$B$601,"Q20"))=0,"",(COUNTIFS('Theo dõi'!$A$2:$A$601,$A7,'Theo dõi'!$D$2:$D$601,"Gemini",'Theo dõi'!$F$2:$F$601,"Có")-COUNTIFS('Theo dõi'!$A$2:$A$601,$A7,'Theo dõi'!$D$2:$D$601,"Gemini",'Theo dõi'!$F$2:$F$601,"Có",'Theo dõi'!$B$2:$B$601,"Q18")-COUNTIFS('Theo dõi'!$A$2:$A$601,$A7,'Theo dõi'!$D$2:$D$601,"Gemini",'Theo dõi'!$F$2:$F$601,"Có",'Theo dõi'!$B$2:$B$601,"Q19")-COUNTIFS('Theo dõi'!$A$2:$A$601,$A7,'Theo dõi'!$D$2:$D$601,"Gemini",'Theo dõi'!$F$2:$F$601,"Có",'Theo dõi'!$B$2:$B$601,"Q20"))/(COUNTIFS('Theo dõi'!$A$2:$A$601,$A7,'Theo dõi'!$D$2:$D$601,"Gemini")-COUNTIFS('Theo dõi'!$A$2:$A$601,$A7,'Theo dõi'!$D$2:$D$601,"Gemini",'Theo dõi'!$B$2:$B$601,"Q18")-COUNTIFS('Theo dõi'!$A$2:$A$601,$A7,'Theo dõi'!$D$2:$D$601,"Gemini",'Theo dõi'!$B$2:$B$601,"Q19")-COUNTIFS('Theo dõi'!$A$2:$A$601,$A7,'Theo dõi'!$D$2:$D$601,"Gemini",'Theo dõi'!$B$2:$B$601,"Q20"))) | F7: =IF((COUNTIFS('Theo dõi'!$A$2:$A$601,$A7,'Theo dõi'!$D$2:$D$601,"Google AI Overview")-COUNTIFS('Theo dõi'!$A$2:$A$601,$A7,'Theo dõi'!$D$2:$D$601,"Google AI Overview",'Theo dõi'!$B$2:$B$601,"Q18")-COUNTIFS('Theo dõi'!$A$2:$A$601,$A7,'Theo dõi'!$D$2:$D$601,"Google AI Overview",'Theo dõi'!$B$2:$B$601,"Q19")-COUNTIFS('Theo dõi'!$A$2:$A$601,$A7,'Theo dõi'!$D$2:$D$601,"Google AI Overview",'Theo dõi'!$B$2:$B$601,"Q20"))=0,"",(COUNTIFS('Theo dõi'!$A$2:$A$601,$A7,'Theo dõi'!$D$2:$D$601,"Google AI Overview",'Theo dõi'!$F$2:$F$601,"Có")-COUNTIFS('Theo dõi'!$A$2:$A$601,$A7,'Theo dõi'!$D$2:$D$601,"Google AI Overview",'Theo dõi'!$F$2:$F$601,"Có",'Theo dõi'!$B$2:$B$601,"Q18")-COUNTIFS('Theo dõi'!$A$2:$A$601,$A7,'Theo dõi'!$D$2:$D$601,"Google AI Overview",'Theo dõi'!$F$2:$F$601,"Có",'Theo dõi'!$B$2:$B$601,"Q19")-COUNTIFS('Theo dõi'!$A$2:$A$601,$A7,'Theo dõi'!$D$2:$D$601,"Google AI Overview",'Theo dõi'!$F$2:$F$601,"Có",'Theo dõi'!$B$2:$B$601,"Q20"))/(COUNTIFS('Theo dõi'!$A$2:$A$601,$A7,'Theo dõi'!$D$2:$D$601,"Google AI Overview")-COUNTIFS('Theo dõi'!$A$2:$A$601,$A7,'Theo dõi'!$D$2:$D$601,"Google AI Overview",'Theo dõi'!$B$2:$B$601,"Q18")-COUNTIFS('Theo dõi'!$A$2:$A$601,$A7,'Theo dõi'!$D$2:$D$601,"Google AI Overview",'Theo dõi'!$B$2:$B$601,"Q19")-COUNTIFS('Theo dõi'!$A$2:$A$601,$A7,'Theo dõi'!$D$2:$D$601,"Google AI Overview",'Theo dõi'!$B$2:$B$601,"Q20"))) | G7: =IF((COUNTIFS('Theo dõi'!$A$2:$A$601,$A7,'Theo dõi'!$D$2:$D$601,"Copilot")-COUNTIFS('Theo dõi'!$A$2:$A$601,$A7,'Theo dõi'!$D$2:$D$601,"Copilot",'Theo dõi'!$B$2:$B$601,"Q18")-COUNTIFS('Theo dõi'!$A$2:$A$601,$A7,'Theo dõi'!$D$2:$D$601,"Copilot",'Theo dõi'!$B$2:$B$601,"Q19")-COUNTIFS('Theo dõi'!$A$2:$A$601,$A7,'Theo dõi'!$D$2:$D$601,"Copilot",'Theo dõi'!$B$2:$B$601,"Q20"))=0,"",(COUNTIFS('Theo dõi'!$A$2:$A$601,$A7,'Theo dõi'!$D$2:$D$601,"Copilot",'Theo dõi'!$F$2:$F$601,"Có")-COUNTIFS('Theo dõi'!$A$2:$A$601,$A7,'Theo dõi'!$D$2:$D$601,"Copilot",'Theo dõi'!$F$2:$F$601,"Có",'Theo dõi'!$B$2:$B$601,"Q18")-COUNTIFS('Theo dõi'!$A$2:$A$601,$A7,'Theo dõi'!$D$2:$D$601,"Copilot",'Theo dõi'!$F$2:$F$601,"Có",'Theo dõi'!$B$2:$B$601,"Q19")-COUNTIFS('Theo dõi'!$A$2:$A$601,$A7,'Theo dõi'!$D$2:$D$601,"Copilot",'Theo dõi'!$F$2:$F$601,"Có",'Theo dõi'!$B$2:$B$601,"Q20"))/(COUNTIFS('Theo dõi'!$A$2:$A$601,$A7,'Theo dõi'!$D$2:$D$601,"Copilot")-COUNTIFS('Theo dõi'!$A$2:$A$601,$A7,'Theo dõi'!$D$2:$D$601,"Copilot",'Theo dõi'!$B$2:$B$601,"Q18")-COUNTIFS('Theo dõi'!$A$2:$A$601,$A7,'Theo dõi'!$D$2:$D$601,"Copilot",'Theo dõi'!$B$2:$B$601,"Q19")-COUNTIFS('Theo dõi'!$A$2:$A$601,$A7,'Theo dõi'!$D$2:$D$601,"Copilot",'Theo dõi'!$B$2:$B$601,"Q20"))) | H7: =IF((COUNTIFS('Theo dõi'!$A$2:$A$601,$A7,'Theo dõi'!$D$2:$D$601,"<>")-COUNTIFS('Theo dõi'!$A$2:$A$601,$A7,'Theo dõi'!$D$2:$D$601,"<>",'Theo dõi'!$B$2:$B$601,"Q18")-COUNTIFS('Theo dõi'!$A$2:$A$601,$A7,'Theo dõi'!$D$2:$D$601,"<>",'Theo dõi'!$B$2:$B$601,"Q19")-COUNTIFS('Theo dõi'!$A$2:$A$601,$A7,'Theo dõi'!$D$2:$D$601,"<>",'Theo dõi'!$B$2:$B$601,"Q20"))=0,"",(COUNTIFS('Theo dõi'!$A$2:$A$601,$A7,'Theo dõi'!$D$2:$D$601,"<>",'Theo dõi'!$F$2:$F$601,"Có")-COUNTIFS('Theo dõi'!$A$2:$A$601,$A7,'Theo dõi'!$D$2:$D$601,"<>",'Theo dõi'!$F$2:$F$601,"Có",'Theo dõi'!$B$2:$B$601,"Q18")-COUNTIFS('Theo dõi'!$A$2:$A$601,$A7,'Theo dõi'!$D$2:$D$601,"<>",'Theo dõi'!$F$2:$F$601,"Có",'Theo dõi'!$B$2:$B$601,"Q19")-COUNTIFS('Theo dõi'!$A$2:$A$601,$A7,'Theo dõi'!$D$2:$D$601,"<>",'Theo dõi'!$F$2:$F$601,"Có",'Theo dõi'!$B$2:$B$601,"Q20"))/(COUNTIFS('Theo dõi'!$A$2:$A$601,$A7,'Theo dõi'!$D$2:$D$601,"<>")-COUNTIFS('Theo dõi'!$A$2:$A$601,$A7,'Theo dõi'!$D$2:$D$601,"<>",'Theo dõi'!$B$2:$B$601,"Q18")-COUNTIFS('Theo dõi'!$A$2:$A$601,$A7,'Theo dõi'!$D$2:$D$601,"<>",'Theo dõi'!$B$2:$B$601,"Q19")-COUNTIFS('Theo dõi'!$A$2:$A$601,$A7,'Theo dõi'!$D$2:$D$601,"<>",'Theo dõi'!$B$2:$B$601,"Q20")))
A8: 2026-12 | B8: =COUNTIFS('Theo dõi'!$A$2:$A$601,$A8,'Theo dõi'!$D$2:$D$601,"<>")-COUNTIFS('Theo dõi'!$A$2:$A$601,$A8,'Theo dõi'!$D$2:$D$601,"<>",'Theo dõi'!$B$2:$B$601,"Q18")-COUNTIFS('Theo dõi'!$A$2:$A$601,$A8,'Theo dõi'!$D$2:$D$601,"<>",'Theo dõi'!$B$2:$B$601,"Q19")-COUNTIFS('Theo dõi'!$A$2:$A$601,$A8,'Theo dõi'!$D$2:$D$601,"<>",'Theo dõi'!$B$2:$B$601,"Q20") -> 0 | C8: =IF((COUNTIFS('Theo dõi'!$A$2:$A$601,$A8,'Theo dõi'!$D$2:$D$601,"ChatGPT")-COUNTIFS('Theo dõi'!$A$2:$A$601,$A8,'Theo dõi'!$D$2:$D$601,"ChatGPT",'Theo dõi'!$B$2:$B$601,"Q18")-COUNTIFS('Theo dõi'!$A$2:$A$601,$A8,'Theo dõi'!$D$2:$D$601,"ChatGPT",'Theo dõi'!$B$2:$B$601,"Q19")-COUNTIFS('Theo dõi'!$A$2:$A$601,$A8,'Theo dõi'!$D$2:$D$601,"ChatGPT",'Theo dõi'!$B$2:$B$601,"Q20"))=0,"",(COUNTIFS('Theo dõi'!$A$2:$A$601,$A8,'Theo dõi'!$D$2:$D$601,"ChatGPT",'Theo dõi'!$F$2:$F$601,"Có")-COUNTIFS('Theo dõi'!$A$2:$A$601,$A8,'Theo dõi'!$D$2:$D$601,"ChatGPT",'Theo dõi'!$F$2:$F$601,"Có",'Theo dõi'!$B$2:$B$601,"Q18")-COUNTIFS('Theo dõi'!$A$2:$A$601,$A8,'Theo dõi'!$D$2:$D$601,"ChatGPT",'Theo dõi'!$F$2:$F$601,"Có",'Theo dõi'!$B$2:$B$601,"Q19")-COUNTIFS('Theo dõi'!$A$2:$A$601,$A8,'Theo dõi'!$D$2:$D$601,"ChatGPT",'Theo dõi'!$F$2:$F$601,"Có",'Theo dõi'!$B$2:$B$601,"Q20"))/(COUNTIFS('Theo dõi'!$A$2:$A$601,$A8,'Theo dõi'!$D$2:$D$601,"ChatGPT")-COUNTIFS('Theo dõi'!$A$2:$A$601,$A8,'Theo dõi'!$D$2:$D$601,"ChatGPT",'Theo dõi'!$B$2:$B$601,"Q18")-COUNTIFS('Theo dõi'!$A$2:$A$601,$A8,'Theo dõi'!$D$2:$D$601,"ChatGPT",'Theo dõi'!$B$2:$B$601,"Q19")-COUNTIFS('Theo dõi'!$A$2:$A$601,$A8,'Theo dõi'!$D$2:$D$601,"ChatGPT",'Theo dõi'!$B$2:$B$601,"Q20"))) | D8: =IF((COUNTIFS('Theo dõi'!$A$2:$A$601,$A8,'Theo dõi'!$D$2:$D$601,"Perplexity")-COUNTIFS('Theo dõi'!$A$2:$A$601,$A8,'Theo dõi'!$D$2:$D$601,"Perplexity",'Theo dõi'!$B$2:$B$601,"Q18")-COUNTIFS('Theo dõi'!$A$2:$A$601,$A8,'Theo dõi'!$D$2:$D$601,"Perplexity",'Theo dõi'!$B$2:$B$601,"Q19")-COUNTIFS('Theo dõi'!$A$2:$A$601,$A8,'Theo dõi'!$D$2:$D$601,"Perplexity",'Theo dõi'!$B$2:$B$601,"Q20"))=0,"",(COUNTIFS('Theo dõi'!$A$2:$A$601,$A8,'Theo dõi'!$D$2:$D$601,"Perplexity",'Theo dõi'!$F$2:$F$601,"Có")-COUNTIFS('Theo dõi'!$A$2:$A$601,$A8,'Theo dõi'!$D$2:$D$601,"Perplexity",'Theo dõi'!$F$2:$F$601,"Có",'Theo dõi'!$B$2:$B$601,"Q18")-COUNTIFS('Theo dõi'!$A$2:$A$601,$A8,'Theo dõi'!$D$2:$D$601,"Perplexity",'Theo dõi'!$F$2:$F$601,"Có",'Theo dõi'!$B$2:$B$601,"Q19")-COUNTIFS('Theo dõi'!$A$2:$A$601,$A8,'Theo dõi'!$D$2:$D$601,"Perplexity",'Theo dõi'!$F$2:$F$601,"Có",'Theo dõi'!$B$2:$B$601,"Q20"))/(COUNTIFS('Theo dõi'!$A$2:$A$601,$A8,'Theo dõi'!$D$2:$D$601,"Perplexity")-COUNTIFS('Theo dõi'!$A$2:$A$601,$A8,'Theo dõi'!$D$2:$D$601,"Perplexity",'Theo dõi'!$B$2:$B$601,"Q18")-COUNTIFS('Theo dõi'!$A$2:$A$601,$A8,'Theo dõi'!$D$2:$D$601,"Perplexity",'Theo dõi'!$B$2:$B$601,"Q19")-COUNTIFS('Theo dõi'!$A$2:$A$601,$A8,'Theo dõi'!$D$2:$D$601,"Perplexity",'Theo dõi'!$B$2:$B$601,"Q20"))) | E8: =IF((COUNTIFS('Theo dõi'!$A$2:$A$601,$A8,'Theo dõi'!$D$2:$D$601,"Gemini")-COUNTIFS('Theo dõi'!$A$2:$A$601,$A8,'Theo dõi'!$D$2:$D$601,"Gemini",'Theo dõi'!$B$2:$B$601,"Q18")-COUNTIFS('Theo dõi'!$A$2:$A$601,$A8,'Theo dõi'!$D$2:$D$601,"Gemini",'Theo dõi'!$B$2:$B$601,"Q19")-COUNTIFS('Theo dõi'!$A$2:$A$601,$A8,'Theo dõi'!$D$2:$D$601,"Gemini",'Theo dõi'!$B$2:$B$601,"Q20"))=0,"",(COUNTIFS('Theo dõi'!$A$2:$A$601,$A8,'Theo dõi'!$D$2:$D$601,"Gemini",'Theo dõi'!$F$2:$F$601,"Có")-COUNTIFS('Theo dõi'!$A$2:$A$601,$A8,'Theo dõi'!$D$2:$D$601,"Gemini",'Theo dõi'!$F$2:$F$601,"Có",'Theo dõi'!$B$2:$B$601,"Q18")-COUNTIFS('Theo dõi'!$A$2:$A$601,$A8,'Theo dõi'!$D$2:$D$601,"Gemini",'Theo dõi'!$F$2:$F$601,"Có",'Theo dõi'!$B$2:$B$601,"Q19")-COUNTIFS('Theo dõi'!$A$2:$A$601,$A8,'Theo dõi'!$D$2:$D$601,"Gemini",'Theo dõi'!$F$2:$F$601,"Có",'Theo dõi'!$B$2:$B$601,"Q20"))/(COUNTIFS('Theo dõi'!$A$2:$A$601,$A8,'Theo dõi'!$D$2:$D$601,"Gemini")-COUNTIFS('Theo dõi'!$A$2:$A$601,$A8,'Theo dõi'!$D$2:$D$601,"Gemini",'Theo dõi'!$B$2:$B$601,"Q18")-COUNTIFS('Theo dõi'!$A$2:$A$601,$A8,'Theo dõi'!$D$2:$D$601,"Gemini",'Theo dõi'!$B$2:$B$601,"Q19")-COUNTIFS('Theo dõi'!$A$2:$A$601,$A8,'Theo dõi'!$D$2:$D$601,"Gemini",'Theo dõi'!$B$2:$B$601,"Q20"))) | F8: =IF((COUNTIFS('Theo dõi'!$A$2:$A$601,$A8,'Theo dõi'!$D$2:$D$601,"Google AI Overview")-COUNTIFS('Theo dõi'!$A$2:$A$601,$A8,'Theo dõi'!$D$2:$D$601,"Google AI Overview",'Theo dõi'!$B$2:$B$601,"Q18")-COUNTIFS('Theo dõi'!$A$2:$A$601,$A8,'Theo dõi'!$D$2:$D$601,"Google AI Overview",'Theo dõi'!$B$2:$B$601,"Q19")-COUNTIFS('Theo dõi'!$A$2:$A$601,$A8,'Theo dõi'!$D$2:$D$601,"Google AI Overview",'Theo dõi'!$B$2:$B$601,"Q20"))=0,"",(COUNTIFS('Theo dõi'!$A$2:$A$601,$A8,'Theo dõi'!$D$2:$D$601,"Google AI Overview",'Theo dõi'!$F$2:$F$601,"Có")-COUNTIFS('Theo dõi'!$A$2:$A$601,$A8,'Theo dõi'!$D$2:$D$601,"Google AI Overview",'Theo dõi'!$F$2:$F$601,"Có",'Theo dõi'!$B$2:$B$601,"Q18")-COUNTIFS('Theo dõi'!$A$2:$A$601,$A8,'Theo dõi'!$D$2:$D$601,"Google AI Overview",'Theo dõi'!$F$2:$F$601,"Có",'Theo dõi'!$B$2:$B$601,"Q19")-COUNTIFS('Theo dõi'!$A$2:$A$601,$A8,'Theo dõi'!$D$2:$D$601,"Google AI Overview",'Theo dõi'!$F$2:$F$601,"Có",'Theo dõi'!$B$2:$B$601,"Q20"))/(COUNTIFS('Theo dõi'!$A$2:$A$601,$A8,'Theo dõi'!$D$2:$D$601,"Google AI Overview")-COUNTIFS('Theo dõi'!$A$2:$A$601,$A8,'Theo dõi'!$D$2:$D$601,"Google AI Overview",'Theo dõi'!$B$2:$B$601,"Q18")-COUNTIFS('Theo dõi'!$A$2:$A$601,$A8,'Theo dõi'!$D$2:$D$601,"Google AI Overview",'Theo dõi'!$B$2:$B$601,"Q19")-COUNTIFS('Theo dõi'!$A$2:$A$601,$A8,'Theo dõi'!$D$2:$D$601,"Google AI Overview",'Theo dõi'!$B$2:$B$601,"Q20"))) | G8: =IF((COUNTIFS('Theo dõi'!$A$2:$A$601,$A8,'Theo dõi'!$D$2:$D$601,"Copilot")-COUNTIFS('Theo dõi'!$A$2:$A$601,$A8,'Theo dõi'!$D$2:$D$601,"Copilot",'Theo dõi'!$B$2:$B$601,"Q18")-COUNTIFS('Theo dõi'!$A$2:$A$601,$A8,'Theo dõi'!$D$2:$D$601,"Copilot",'Theo dõi'!$B$2:$B$601,"Q19")-COUNTIFS('Theo dõi'!$A$2:$A$601,$A8,'Theo dõi'!$D$2:$D$601,"Copilot",'Theo dõi'!$B$2:$B$601,"Q20"))=0,"",(COUNTIFS('Theo dõi'!$A$2:$A$601,$A8,'Theo dõi'!$D$2:$D$601,"Copilot",'Theo dõi'!$F$2:$F$601,"Có")-COUNTIFS('Theo dõi'!$A$2:$A$601,$A8,'Theo dõi'!$D$2:$D$601,"Copilot",'Theo dõi'!$F$2:$F$601,"Có",'Theo dõi'!$B$2:$B$601,"Q18")-COUNTIFS('Theo dõi'!$A$2:$A$601,$A8,'Theo dõi'!$D$2:$D$601,"Copilot",'Theo dõi'!$F$2:$F$601,"Có",'Theo dõi'!$B$2:$B$601,"Q19")-COUNTIFS('Theo dõi'!$A$2:$A$601,$A8,'Theo dõi'!$D$2:$D$601,"Copilot",'Theo dõi'!$F$2:$F$601,"Có",'Theo dõi'!$B$2:$B$601,"Q20"))/(COUNTIFS('Theo dõi'!$A$2:$A$601,$A8,'Theo dõi'!$D$2:$D$601,"Copilot")-COUNTIFS('Theo dõi'!$A$2:$A$601,$A8,'Theo dõi'!$D$2:$D$601,"Copilot",'Theo dõi'!$B$2:$B$601,"Q18")-COUNTIFS('Theo dõi'!$A$2:$A$601,$A8,'Theo dõi'!$D$2:$D$601,"Copilot",'Theo dõi'!$B$2:$B$601,"Q19")-COUNTIFS('Theo dõi'!$A$2:$A$601,$A8,'Theo dõi'!$D$2:$D$601,"Copilot",'Theo dõi'!$B$2:$B$601,"Q20"))) | H8: =IF((COUNTIFS('Theo dõi'!$A$2:$A$601,$A8,'Theo dõi'!$D$2:$D$601,"<>")-COUNTIFS('Theo dõi'!$A$2:$A$601,$A8,'Theo dõi'!$D$2:$D$601,"<>",'Theo dõi'!$B$2:$B$601,"Q18")-COUNTIFS('Theo dõi'!$A$2:$A$601,$A8,'Theo dõi'!$D$2:$D$601,"<>",'Theo dõi'!$B$2:$B$601,"Q19")-COUNTIFS('Theo dõi'!$A$2:$A$601,$A8,'Theo dõi'!$D$2:$D$601,"<>",'Theo dõi'!$B$2:$B$601,"Q20"))=0,"",(COUNTIFS('Theo dõi'!$A$2:$A$601,$A8,'Theo dõi'!$D$2:$D$601,"<>",'Theo dõi'!$F$2:$F$601,"Có")-COUNTIFS('Theo dõi'!$A$2:$A$601,$A8,'Theo dõi'!$D$2:$D$601,"<>",'Theo dõi'!$F$2:$F$601,"Có",'Theo dõi'!$B$2:$B$601,"Q18")-COUNTIFS('Theo dõi'!$A$2:$A$601,$A8,'Theo dõi'!$D$2:$D$601,"<>",'Theo dõi'!$F$2:$F$601,"Có",'Theo dõi'!$B$2:$B$601,"Q19")-COUNTIFS('Theo dõi'!$A$2:$A$601,$A8,'Theo dõi'!$D$2:$D$601,"<>",'Theo dõi'!$F$2:$F$601,"Có",'Theo dõi'!$B$2:$B$601,"Q20"))/(COUNTIFS('Theo dõi'!$A$2:$A$601,$A8,'Theo dõi'!$D$2:$D$601,"<>")-COUNTIFS('Theo dõi'!$A$2:$A$601,$A8,'Theo dõi'!$D$2:$D$601,"<>",'Theo dõi'!$B$2:$B$601,"Q18")-COUNTIFS('Theo dõi'!$A$2:$A$601,$A8,'Theo dõi'!$D$2:$D$601,"<>",'Theo dõi'!$B$2:$B$601,"Q19")-COUNTIFS('Theo dõi'!$A$2:$A$601,$A8,'Theo dõi'!$D$2:$D$601,"<>",'Theo dõi'!$B$2:$B$601,"Q20")))
A9: 2027-01 | B9: =COUNTIFS('Theo dõi'!$A$2:$A$601,$A9,'Theo dõi'!$D$2:$D$601,"<>")-COUNTIFS('Theo dõi'!$A$2:$A$601,$A9,'Theo dõi'!$D$2:$D$601,"<>",'Theo dõi'!$B$2:$B$601,"Q18")-COUNTIFS('Theo dõi'!$A$2:$A$601,$A9,'Theo dõi'!$D$2:$D$601,"<>",'Theo dõi'!$B$2:$B$601,"Q19")-COUNTIFS('Theo dõi'!$A$2:$A$601,$A9,'Theo dõi'!$D$2:$D$601,"<>",'Theo dõi'!$B$2:$B$601,"Q20") -> 0 | C9: =IF((COUNTIFS('Theo dõi'!$A$2:$A$601,$A9,'Theo dõi'!$D$2:$D$601,"ChatGPT")-COUNTIFS('Theo dõi'!$A$2:$A$601,$A9,'Theo dõi'!$D$2:$D$601,"ChatGPT",'Theo dõi'!$B$2:$B$601,"Q18")-COUNTIFS('Theo dõi'!$A$2:$A$601,$A9,'Theo dõi'!$D$2:$D$601,"ChatGPT",'Theo dõi'!$B$2:$B$601,"Q19")-COUNTIFS('Theo dõi'!$A$2:$A$601,$A9,'Theo dõi'!$D$2:$D$601,"ChatGPT",'Theo dõi'!$B$2:$B$601,"Q20"))=0,"",(COUNTIFS('Theo dõi'!$A$2:$A$601,$A9,'Theo dõi'!$D$2:$D$601,"ChatGPT",'Theo dõi'!$F$2:$F$601,"Có")-COUNTIFS('Theo dõi'!$A$2:$A$601,$A9,'Theo dõi'!$D$2:$D$601,"ChatGPT",'Theo dõi'!$F$2:$F$601,"Có",'Theo dõi'!$B$2:$B$601,"Q18")-COUNTIFS('Theo dõi'!$A$2:$A$601,$A9,'Theo dõi'!$D$2:$D$601,"ChatGPT",'Theo dõi'!$F$2:$F$601,"Có",'Theo dõi'!$B$2:$B$601,"Q19")-COUNTIFS('Theo dõi'!$A$2:$A$601,$A9,'Theo dõi'!$D$2:$D$601,"ChatGPT",'Theo dõi'!$F$2:$F$601,"Có",'Theo dõi'!$B$2:$B$601,"Q20"))/(COUNTIFS('Theo dõi'!$A$2:$A$601,$A9,'Theo dõi'!$D$2:$D$601,"ChatGPT")-COUNTIFS('Theo dõi'!$A$2:$A$601,$A9,'Theo dõi'!$D$2:$D$601,"ChatGPT",'Theo dõi'!$B$2:$B$601,"Q18")-COUNTIFS('Theo dõi'!$A$2:$A$601,$A9,'Theo dõi'!$D$2:$D$601,"ChatGPT",'Theo dõi'!$B$2:$B$601,"Q19")-COUNTIFS('Theo dõi'!$A$2:$A$601,$A9,'Theo dõi'!$D$2:$D$601,"ChatGPT",'Theo dõi'!$B$2:$B$601,"Q20"))) | D9: =IF((COUNTIFS('Theo dõi'!$A$2:$A$601,$A9,'Theo dõi'!$D$2:$D$601,"Perplexity")-COUNTIFS('Theo dõi'!$A$2:$A$601,$A9,'Theo dõi'!$D$2:$D$601,"Perplexity",'Theo dõi'!$B$2:$B$601,"Q18")-COUNTIFS('Theo dõi'!$A$2:$A$601,$A9,'Theo dõi'!$D$2:$D$601,"Perplexity",'Theo dõi'!$B$2:$B$601,"Q19")-COUNTIFS('Theo dõi'!$A$2:$A$601,$A9,'Theo dõi'!$D$2:$D$601,"Perplexity",'Theo dõi'!$B$2:$B$601,"Q20"))=0,"",(COUNTIFS('Theo dõi'!$A$2:$A$601,$A9,'Theo dõi'!$D$2:$D$601,"Perplexity",'Theo dõi'!$F$2:$F$601,"Có")-COUNTIFS('Theo dõi'!$A$2:$A$601,$A9,'Theo dõi'!$D$2:$D$601,"Perplexity",'Theo dõi'!$F$2:$F$601,"Có",'Theo dõi'!$B$2:$B$601,"Q18")-COUNTIFS('Theo dõi'!$A$2:$A$601,$A9,'Theo dõi'!$D$2:$D$601,"Perplexity",'Theo dõi'!$F$2:$F$601,"Có",'Theo dõi'!$B$2:$B$601,"Q19")-COUNTIFS('Theo dõi'!$A$2:$A$601,$A9,'Theo dõi'!$D$2:$D$601,"Perplexity",'Theo dõi'!$F$2:$F$601,"Có",'Theo dõi'!$B$2:$B$601,"Q20"))/(COUNTIFS('Theo dõi'!$A$2:$A$601,$A9,'Theo dõi'!$D$2:$D$601,"Perplexity")-COUNTIFS('Theo dõi'!$A$2:$A$601,$A9,'Theo dõi'!$D$2:$D$601,"Perplexity",'Theo dõi'!$B$2:$B$601,"Q18")-COUNTIFS('Theo dõi'!$A$2:$A$601,$A9,'Theo dõi'!$D$2:$D$601,"Perplexity",'Theo dõi'!$B$2:$B$601,"Q19")-COUNTIFS('Theo dõi'!$A$2:$A$601,$A9,'Theo dõi'!$D$2:$D$601,"Perplexity",'Theo dõi'!$B$2:$B$601,"Q20"))) | E9: =IF((COUNTIFS('Theo dõi'!$A$2:$A$601,$A9,'Theo dõi'!$D$2:$D$601,"Gemini")-COUNTIFS('Theo dõi'!$A$2:$A$601,$A9,'Theo dõi'!$D$2:$D$601,"Gemini",'Theo dõi'!$B$2:$B$601,"Q18")-COUNTIFS('Theo dõi'!$A$2:$A$601,$A9,'Theo dõi'!$D$2:$D$601,"Gemini",'Theo dõi'!$B$2:$B$601,"Q19")-COUNTIFS('Theo dõi'!$A$2:$A$601,$A9,'Theo dõi'!$D$2:$D$601,"Gemini",'Theo dõi'!$B$2:$B$601,"Q20"))=0,"",(COUNTIFS('Theo dõi'!$A$2:$A$601,$A9,'Theo dõi'!$D$2:$D$601,"Gemini",'Theo dõi'!$F$2:$F$601,"Có")-COUNTIFS('Theo dõi'!$A$2:$A$601,$A9,'Theo dõi'!$D$2:$D$601,"Gemini",'Theo dõi'!$F$2:$F$601,"Có",'Theo dõi'!$B$2:$B$601,"Q18")-COUNTIFS('Theo dõi'!$A$2:$A$601,$A9,'Theo dõi'!$D$2:$D$601,"Gemini",'Theo dõi'!$F$2:$F$601,"Có",'Theo dõi'!$B$2:$B$601,"Q19")-COUNTIFS('Theo dõi'!$A$2:$A$601,$A9,'Theo dõi'!$D$2:$D$601,"Gemini",'Theo dõi'!$F$2:$F$601,"Có",'Theo dõi'!$B$2:$B$601,"Q20"))/(COUNTIFS('Theo dõi'!$A$2:$A$601,$A9,'Theo dõi'!$D$2:$D$601,"Gemini")-COUNTIFS('Theo dõi'!$A$2:$A$601,$A9,'Theo dõi'!$D$2:$D$601,"Gemini",'Theo dõi'!$B$2:$B$601,"Q18")-COUNTIFS('Theo dõi'!$A$2:$A$601,$A9,'Theo dõi'!$D$2:$D$601,"Gemini",'Theo dõi'!$B$2:$B$601,"Q19")-COUNTIFS('Theo dõi'!$A$2:$A$601,$A9,'Theo dõi'!$D$2:$D$601,"Gemini",'Theo dõi'!$B$2:$B$601,"Q20"))) | F9: =IF((COUNTIFS('Theo dõi'!$A$2:$A$601,$A9,'Theo dõi'!$D$2:$D$601,"Google AI Overview")-COUNTIFS('Theo dõi'!$A$2:$A$601,$A9,'Theo dõi'!$D$2:$D$601,"Google AI Overview",'Theo dõi'!$B$2:$B$601,"Q18")-COUNTIFS('Theo dõi'!$A$2:$A$601,$A9,'Theo dõi'!$D$2:$D$601,"Google AI Overview",'Theo dõi'!$B$2:$B$601,"Q19")-COUNTIFS('Theo dõi'!$A$2:$A$601,$A9,'Theo dõi'!$D$2:$D$601,"Google AI Overview",'Theo dõi'!$B$2:$B$601,"Q20"))=0,"",(COUNTIFS('Theo dõi'!$A$2:$A$601,$A9,'Theo dõi'!$D$2:$D$601,"Google AI Overview",'Theo dõi'!$F$2:$F$601,"Có")-COUNTIFS('Theo dõi'!$A$2:$A$601,$A9,'Theo dõi'!$D$2:$D$601,"Google AI Overview",'Theo dõi'!$F$2:$F$601,"Có",'Theo dõi'!$B$2:$B$601,"Q18")-COUNTIFS('Theo dõi'!$A$2:$A$601,$A9,'Theo dõi'!$D$2:$D$601,"Google AI Overview",'Theo dõi'!$F$2:$F$601,"Có",'Theo dõi'!$B$2:$B$601,"Q19")-COUNTIFS('Theo dõi'!$A$2:$A$601,$A9,'Theo dõi'!$D$2:$D$601,"Google AI Overview",'Theo dõi'!$F$2:$F$601,"Có",'Theo dõi'!$B$2:$B$601,"Q20"))/(COUNTIFS('Theo dõi'!$A$2:$A$601,$A9,'Theo dõi'!$D$2:$D$601,"Google AI Overview")-COUNTIFS('Theo dõi'!$A$2:$A$601,$A9,'Theo dõi'!$D$2:$D$601,"Google AI Overview",'Theo dõi'!$B$2:$B$601,"Q18")-COUNTIFS('Theo dõi'!$A$2:$A$601,$A9,'Theo dõi'!$D$2:$D$601,"Google AI Overview",'Theo dõi'!$B$2:$B$601,"Q19")-COUNTIFS('Theo dõi'!$A$2:$A$601,$A9,'Theo dõi'!$D$2:$D$601,"Google AI Overview",'Theo dõi'!$B$2:$B$601,"Q20"))) | G9: =IF((COUNTIFS('Theo dõi'!$A$2:$A$601,$A9,'Theo dõi'!$D$2:$D$601,"Copilot")-COUNTIFS('Theo dõi'!$A$2:$A$601,$A9,'Theo dõi'!$D$2:$D$601,"Copilot",'Theo dõi'!$B$2:$B$601,"Q18")-COUNTIFS('Theo dõi'!$A$2:$A$601,$A9,'Theo dõi'!$D$2:$D$601,"Copilot",'Theo dõi'!$B$2:$B$601,"Q19")-COUNTIFS('Theo dõi'!$A$2:$A$601,$A9,'Theo dõi'!$D$2:$D$601,"Copilot",'Theo dõi'!$B$2:$B$601,"Q20"))=0,"",(COUNTIFS('Theo dõi'!$A$2:$A$601,$A9,'Theo dõi'!$D$2:$D$601,"Copilot",'Theo dõi'!$F$2:$F$601,"Có")-COUNTIFS('Theo dõi'!$A$2:$A$601,$A9,'Theo dõi'!$D$2:$D$601,"Copilot",'Theo dõi'!$F$2:$F$601,"Có",'Theo dõi'!$B$2:$B$601,"Q18")-COUNTIFS('Theo dõi'!$A$2:$A$601,$A9,'Theo dõi'!$D$2:$D$601,"Copilot",'Theo dõi'!$F$2:$F$601,"Có",'Theo dõi'!$B$2:$B$601,"Q19")-COUNTIFS('Theo dõi'!$A$2:$A$601,$A9,'Theo dõi'!$D$2:$D$601,"Copilot",'Theo dõi'!$F$2:$F$601,"Có",'Theo dõi'!$B$2:$B$601,"Q20"))/(COUNTIFS('Theo dõi'!$A$2:$A$601,$A9,'Theo dõi'!$D$2:$D$601,"Copilot")-COUNTIFS('Theo dõi'!$A$2:$A$601,$A9,'Theo dõi'!$D$2:$D$601,"Copilot",'Theo dõi'!$B$2:$B$601,"Q18")-COUNTIFS('Theo dõi'!$A$2:$A$601,$A9,'Theo dõi'!$D$2:$D$601,"Copilot",'Theo dõi'!$B$2:$B$601,"Q19")-COUNTIFS('Theo dõi'!$A$2:$A$601,$A9,'Theo dõi'!$D$2:$D$601,"Copilot",'Theo dõi'!$B$2:$B$601,"Q20"))) | H9: =IF((COUNTIFS('Theo dõi'!$A$2:$A$601,$A9,'Theo dõi'!$D$2:$D$601,"<>")-COUNTIFS('Theo dõi'!$A$2:$A$601,$A9,'Theo dõi'!$D$2:$D$601,"<>",'Theo dõi'!$B$2:$B$601,"Q18")-COUNTIFS('Theo dõi'!$A$2:$A$601,$A9,'Theo dõi'!$D$2:$D$601,"<>",'Theo dõi'!$B$2:$B$601,"Q19")-COUNTIFS('Theo dõi'!$A$2:$A$601,$A9,'Theo dõi'!$D$2:$D$601,"<>",'Theo dõi'!$B$2:$B$601,"Q20"))=0,"",(COUNTIFS('Theo dõi'!$A$2:$A$601,$A9,'Theo dõi'!$D$2:$D$601,"<>",'Theo dõi'!$F$2:$F$601,"Có")-COUNTIFS('Theo dõi'!$A$2:$A$601,$A9,'Theo dõi'!$D$2:$D$601,"<>",'Theo dõi'!$F$2:$F$601,"Có",'Theo dõi'!$B$2:$B$601,"Q18")-COUNTIFS('Theo dõi'!$A$2:$A$601,$A9,'Theo dõi'!$D$2:$D$601,"<>",'Theo dõi'!$F$2:$F$601,"Có",'Theo dõi'!$B$2:$B$601,"Q19")-COUNTIFS('Theo dõi'!$A$2:$A$601,$A9,'Theo dõi'!$D$2:$D$601,"<>",'Theo dõi'!$F$2:$F$601,"Có",'Theo dõi'!$B$2:$B$601,"Q20"))/(COUNTIFS('Theo dõi'!$A$2:$A$601,$A9,'Theo dõi'!$D$2:$D$601,"<>")-COUNTIFS('Theo dõi'!$A$2:$A$601,$A9,'Theo dõi'!$D$2:$D$601,"<>",'Theo dõi'!$B$2:$B$601,"Q18")-COUNTIFS('Theo dõi'!$A$2:$A$601,$A9,'Theo dõi'!$D$2:$D$601,"<>",'Theo dõi'!$B$2:$B$601,"Q19")-COUNTIFS('Theo dõi'!$A$2:$A$601,$A9,'Theo dõi'!$D$2:$D$601,"<>",'Theo dõi'!$B$2:$B$601,"Q20")))
A10: 2027-02 | B10: =COUNTIFS('Theo dõi'!$A$2:$A$601,$A10,'Theo dõi'!$D$2:$D$601,"<>")-COUNTIFS('Theo dõi'!$A$2:$A$601,$A10,'Theo dõi'!$D$2:$D$601,"<>",'Theo dõi'!$B$2:$B$601,"Q18")-COUNTIFS('Theo dõi'!$A$2:$A$601,$A10,'Theo dõi'!$D$2:$D$601,"<>",'Theo dõi'!$B$2:$B$601,"Q19")-COUNTIFS('Theo dõi'!$A$2:$A$601,$A10,'Theo dõi'!$D$2:$D$601,"<>",'Theo dõi'!$B$2:$B$601,"Q20") -> 0 | C10: =IF((COUNTIFS('Theo dõi'!$A$2:$A$601,$A10,'Theo dõi'!$D$2:$D$601,"ChatGPT")-COUNTIFS('Theo dõi'!$A$2:$A$601,$A10,'Theo dõi'!$D$2:$D$601,"ChatGPT",'Theo dõi'!$B$2:$B$601,"Q18")-COUNTIFS('Theo dõi'!$A$2:$A$601,$A10,'Theo dõi'!$D$2:$D$601,"ChatGPT",'Theo dõi'!$B$2:$B$601,"Q19")-COUNTIFS('Theo dõi'!$A$2:$A$601,$A10,'Theo dõi'!$D$2:$D$601,"ChatGPT",'Theo dõi'!$B$2:$B$601,"Q20"))=0,"",(COUNTIFS('Theo dõi'!$A$2:$A$601,$A10,'Theo dõi'!$D$2:$D$601,"ChatGPT",'Theo dõi'!$F$2:$F$601,"Có")-COUNTIFS('Theo dõi'!$A$2:$A$601,$A10,'Theo dõi'!$D$2:$D$601,"ChatGPT",'Theo dõi'!$F$2:$F$601,"Có",'Theo dõi'!$B$2:$B$601,"Q18")-COUNTIFS('Theo dõi'!$A$2:$A$601,$A10,'Theo dõi'!$D$2:$D$601,"ChatGPT",'Theo dõi'!$F$2:$F$601,"Có",'Theo dõi'!$B$2:$B$601,"Q19")-COUNTIFS('Theo dõi'!$A$2:$A$601,$A10,'Theo dõi'!$D$2:$D$601,"ChatGPT",'Theo dõi'!$F$2:$F$601,"Có",'Theo dõi'!$B$2:$B$601,"Q20"))/(COUNTIFS('Theo dõi'!$A$2:$A$601,$A10,'Theo dõi'!$D$2:$D$601,"ChatGPT")-COUNTIFS('Theo dõi'!$A$2:$A$601,$A10,'Theo dõi'!$D$2:$D$601,"ChatGPT",'Theo dõi'!$B$2:$B$601,"Q18")-COUNTIFS('Theo dõi'!$A$2:$A$601,$A10,'Theo dõi'!$D$2:$D$601,"ChatGPT",'Theo dõi'!$B$2:$B$601,"Q19")-COUNTIFS('Theo dõi'!$A$2:$A$601,$A10,'Theo dõi'!$D$2:$D$601,"ChatGPT",'Theo dõi'!$B$2:$B$601,"Q20"))) | D10: =IF((COUNTIFS('Theo dõi'!$A$2:$A$601,$A10,'Theo dõi'!$D$2:$D$601,"Perplexity")-COUNTIFS('Theo dõi'!$A$2:$A$601,$A10,'Theo dõi'!$D$2:$D$601,"Perplexity",'Theo dõi'!$B$2:$B$601,"Q18")-COUNTIFS('Theo dõi'!$A$2:$A$601,$A10,'Theo dõi'!$D$2:$D$601,"Perplexity",'Theo dõi'!$B$2:$B$601,"Q19")-COUNTIFS('Theo dõi'!$A$2:$A$601,$A10,'Theo dõi'!$D$2:$D$601,"Perplexity",'Theo dõi'!$B$2:$B$601,"Q20"))=0,"",(COUNTIFS('Theo dõi'!$A$2:$A$601,$A10,'Theo dõi'!$D$2:$D$601,"Perplexity",'Theo dõi'!$F$2:$F$601,"Có")-COUNTIFS('Theo dõi'!$A$2:$A$601,$A10,'Theo dõi'!$D$2:$D$601,"Perplexity",'Theo dõi'!$F$2:$F$601,"Có",'Theo dõi'!$B$2:$B$601,"Q18")-COUNTIFS('Theo dõi'!$A$2:$A$601,$A10,'Theo dõi'!$D$2:$D$601,"Perplexity",'Theo dõi'!$F$2:$F$601,"Có",'Theo dõi'!$B$2:$B$601,"Q19")-COUNTIFS('Theo dõi'!$A$2:$A$601,$A10,'Theo dõi'!$D$2:$D$601,"Perplexity",'Theo dõi'!$F$2:$F$601,"Có",'Theo dõi'!$B$2:$B$601,"Q20"))/(COUNTIFS('Theo dõi'!$A$2:$A$601,$A10,'Theo dõi'!$D$2:$D$601,"Perplexity")-COUNTIFS('Theo dõi'!$A$2:$A$601,$A10,'Theo dõi'!$D$2:$D$601,"Perplexity",'Theo dõi'!$B$2:$B$601,"Q18")-COUNTIFS('Theo dõi'!$A$2:$A$601,$A10,'Theo dõi'!$D$2:$D$601,"Perplexity",'Theo dõi'!$B$2:$B$601,"Q19")-COUNTIFS('Theo dõi'!$A$2:$A$601,$A10,'Theo dõi'!$D$2:$D$601,"Perplexity",'Theo dõi'!$B$2:$B$601,"Q20"))) | E10: =IF((COUNTIFS('Theo dõi'!$A$2:$A$601,$A10,'Theo dõi'!$D$2:$D$601,"Gemini")-COUNTIFS('Theo dõi'!$A$2:$A$601,$A10,'Theo dõi'!$D$2:$D$601,"Gemini",'Theo dõi'!$B$2:$B$601,"Q18")-COUNTIFS('Theo dõi'!$A$2:$A$601,$A10,'Theo dõi'!$D$2:$D$601,"Gemini",'Theo dõi'!$B$2:$B$601,"Q19")-COUNTIFS('Theo dõi'!$A$2:$A$601,$A10,'Theo dõi'!$D$2:$D$601,"Gemini",'Theo dõi'!$B$2:$B$601,"Q20"))=0,"",(COUNTIFS('Theo dõi'!$A$2:$A$601,$A10,'Theo dõi'!$D$2:$D$601,"Gemini",'Theo dõi'!$F$2:$F$601,"Có")-COUNTIFS('Theo dõi'!$A$2:$A$601,$A10,'Theo dõi'!$D$2:$D$601,"Gemini",'Theo dõi'!$F$2:$F$601,"Có",'Theo dõi'!$B$2:$B$601,"Q18")-COUNTIFS('Theo dõi'!$A$2:$A$601,$A10,'Theo dõi'!$D$2:$D$601,"Gemini",'Theo dõi'!$F$2:$F$601,"Có",'Theo dõi'!$B$2:$B$601,"Q19")-COUNTIFS('Theo dõi'!$A$2:$A$601,$A10,'Theo dõi'!$D$2:$D$601,"Gemini",'Theo dõi'!$F$2:$F$601,"Có",'Theo dõi'!$B$2:$B$601,"Q20"))/(COUNTIFS('Theo dõi'!$A$2:$A$601,$A10,'Theo dõi'!$D$2:$D$601,"Gemini")-COUNTIFS('Theo dõi'!$A$2:$A$601,$A10,'Theo dõi'!$D$2:$D$601,"Gemini",'Theo dõi'!$B$2:$B$601,"Q18")-COUNTIFS('Theo dõi'!$A$2:$A$601,$A10,'Theo dõi'!$D$2:$D$601,"Gemini",'Theo dõi'!$B$2:$B$601,"Q19")-COUNTIFS('Theo dõi'!$A$2:$A$601,$A10,'Theo dõi'!$D$2:$D$601,"Gemini",'Theo dõi'!$B$2:$B$601,"Q20"))) | F10: =IF((COUNTIFS('Theo dõi'!$A$2:$A$601,$A10,'Theo dõi'!$D$2:$D$601,"Google AI Overview")-COUNTIFS('Theo dõi'!$A$2:$A$601,$A10,'Theo dõi'!$D$2:$D$601,"Google AI Overview",'Theo dõi'!$B$2:$B$601,"Q18")-COUNTIFS('Theo dõi'!$A$2:$A$601,$A10,'Theo dõi'!$D$2:$D$601,"Google AI Overview",'Theo dõi'!$B$2:$B$601,"Q19")-COUNTIFS('Theo dõi'!$A$2:$A$601,$A10,'Theo dõi'!$D$2:$D$601,"Google AI Overview",'Theo dõi'!$B$2:$B$601,"Q20"))=0,"",(COUNTIFS('Theo dõi'!$A$2:$A$601,$A10,'Theo dõi'!$D$2:$D$601,"Google AI Overview",'Theo dõi'!$F$2:$F$601,"Có")-COUNTIFS('Theo dõi'!$A$2:$A$601,$A10,'Theo dõi'!$D$2:$D$601,"Google AI Overview",'Theo dõi'!$F$2:$F$601,"Có",'Theo dõi'!$B$2:$B$601,"Q18")-COUNTIFS('Theo dõi'!$A$2:$A$601,$A10,'Theo dõi'!$D$2:$D$601,"Google AI Overview",'Theo dõi'!$F$2:$F$601,"Có",'Theo dõi'!$B$2:$B$601,"Q19")-COUNTIFS('Theo dõi'!$A$2:$A$601,$A10,'Theo dõi'!$D$2:$D$601,"Google AI Overview",'Theo dõi'!$F$2:$F$601,"Có",'Theo dõi'!$B$2:$B$601,"Q20"))/(COUNTIFS('Theo dõi'!$A$2:$A$601,$A10,'Theo dõi'!$D$2:$D$601,"Google AI Overview")-COUNTIFS('Theo dõi'!$A$2:$A$601,$A10,'Theo dõi'!$D$2:$D$601,"Google AI Overview",'Theo dõi'!$B$2:$B$601,"Q18")-COUNTIFS('Theo dõi'!$A$2:$A$601,$A10,'Theo dõi'!$D$2:$D$601,"Google AI Overview",'Theo dõi'!$B$2:$B$601,"Q19")-COUNTIFS('Theo dõi'!$A$2:$A$601,$A10,'Theo dõi'!$D$2:$D$601,"Google AI Overview",'Theo dõi'!$B$2:$B$601,"Q20"))) | G10: =IF((COUNTIFS('Theo dõi'!$A$2:$A$601,$A10,'Theo dõi'!$D$2:$D$601,"Copilot")-COUNTIFS('Theo dõi'!$A$2:$A$601,$A10,'Theo dõi'!$D$2:$D$601,"Copilot",'Theo dõi'!$B$2:$B$601,"Q18")-COUNTIFS('Theo dõi'!$A$2:$A$601,$A10,'Theo dõi'!$D$2:$D$601,"Copilot",'Theo dõi'!$B$2:$B$601,"Q19")-COUNTIFS('Theo dõi'!$A$2:$A$601,$A10,'Theo dõi'!$D$2:$D$601,"Copilot",'Theo dõi'!$B$2:$B$601,"Q20"))=0,"",(COUNTIFS('Theo dõi'!$A$2:$A$601,$A10,'Theo dõi'!$D$2:$D$601,"Copilot",'Theo dõi'!$F$2:$F$601,"Có")-COUNTIFS('Theo dõi'!$A$2:$A$601,$A10,'Theo dõi'!$D$2:$D$601,"Copilot",'Theo dõi'!$F$2:$F$601,"Có",'Theo dõi'!$B$2:$B$601,"Q18")-COUNTIFS('Theo dõi'!$A$2:$A$601,$A10,'Theo dõi'!$D$2:$D$601,"Copilot",'Theo dõi'!$F$2:$F$601,"Có",'Theo dõi'!$B$2:$B$601,"Q19")-COUNTIFS('Theo dõi'!$A$2:$A$601,$A10,'Theo dõi'!$D$2:$D$601,"Copilot",'Theo dõi'!$F$2:$F$601,"Có",'Theo dõi'!$B$2:$B$601,"Q20"))/(COUNTIFS('Theo dõi'!$A$2:$A$601,$A10,'Theo dõi'!$D$2:$D$601,"Copilot")-COUNTIFS('Theo dõi'!$A$2:$A$601,$A10,'Theo dõi'!$D$2:$D$601,"Copilot",'Theo dõi'!$B$2:$B$601,"Q18")-COUNTIFS('Theo dõi'!$A$2:$A$601,$A10,'Theo dõi'!$D$2:$D$601,"Copilot",'Theo dõi'!$B$2:$B$601,"Q19")-COUNTIFS('Theo dõi'!$A$2:$A$601,$A10,'Theo dõi'!$D$2:$D$601,"Copilot",'Theo dõi'!$B$2:$B$601,"Q20"))) | H10: =IF((COUNTIFS('Theo dõi'!$A$2:$A$601,$A10,'Theo dõi'!$D$2:$D$601,"<>")-COUNTIFS('Theo dõi'!$A$2:$A$601,$A10,'Theo dõi'!$D$2:$D$601,"<>",'Theo dõi'!$B$2:$B$601,"Q18")-COUNTIFS('Theo dõi'!$A$2:$A$601,$A10,'Theo dõi'!$D$2:$D$601,"<>",'Theo dõi'!$B$2:$B$601,"Q19")-COUNTIFS('Theo dõi'!$A$2:$A$601,$A10,'Theo dõi'!$D$2:$D$601,"<>",'Theo dõi'!$B$2:$B$601,"Q20"))=0,"",(COUNTIFS('Theo dõi'!$A$2:$A$601,$A10,'Theo dõi'!$D$2:$D$601,"<>",'Theo dõi'!$F$2:$F$601,"Có")-COUNTIFS('Theo dõi'!$A$2:$A$601,$A10,'Theo dõi'!$D$2:$D$601,"<>",'Theo dõi'!$F$2:$F$601,"Có",'Theo dõi'!$B$2:$B$601,"Q18")-COUNTIFS('Theo dõi'!$A$2:$A$601,$A10,'Theo dõi'!$D$2:$D$601,"<>",'Theo dõi'!$F$2:$F$601,"Có",'Theo dõi'!$B$2:$B$601,"Q19")-COUNTIFS('Theo dõi'!$A$2:$A$601,$A10,'Theo dõi'!$D$2:$D$601,"<>",'Theo dõi'!$F$2:$F$601,"Có",'Theo dõi'!$B$2:$B$601,"Q20"))/(COUNTIFS('Theo dõi'!$A$2:$A$601,$A10,'Theo dõi'!$D$2:$D$601,"<>")-COUNTIFS('Theo dõi'!$A$2:$A$601,$A10,'Theo dõi'!$D$2:$D$601,"<>",'Theo dõi'!$B$2:$B$601,"Q18")-COUNTIFS('Theo dõi'!$A$2:$A$601,$A10,'Theo dõi'!$D$2:$D$601,"<>",'Theo dõi'!$B$2:$B$601,"Q19")-COUNTIFS('Theo dõi'!$A$2:$A$601,$A10,'Theo dõi'!$D$2:$D$601,"<>",'Theo dõi'!$B$2:$B$601,"Q20")))
A11: 2027-03 | B11: =COUNTIFS('Theo dõi'!$A$2:$A$601,$A11,'Theo dõi'!$D$2:$D$601,"<>")-COUNTIFS('Theo dõi'!$A$2:$A$601,$A11,'Theo dõi'!$D$2:$D$601,"<>",'Theo dõi'!$B$2:$B$601,"Q18")-COUNTIFS('Theo dõi'!$A$2:$A$601,$A11,'Theo dõi'!$D$2:$D$601,"<>",'Theo dõi'!$B$2:$B$601,"Q19")-COUNTIFS('Theo dõi'!$A$2:$A$601,$A11,'Theo dõi'!$D$2:$D$601,"<>",'Theo dõi'!$B$2:$B$601,"Q20") -> 0 | C11: =IF((COUNTIFS('Theo dõi'!$A$2:$A$601,$A11,'Theo dõi'!$D$2:$D$601,"ChatGPT")-COUNTIFS('Theo dõi'!$A$2:$A$601,$A11,'Theo dõi'!$D$2:$D$601,"ChatGPT",'Theo dõi'!$B$2:$B$601,"Q18")-COUNTIFS('Theo dõi'!$A$2:$A$601,$A11,'Theo dõi'!$D$2:$D$601,"ChatGPT",'Theo dõi'!$B$2:$B$601,"Q19")-COUNTIFS('Theo dõi'!$A$2:$A$601,$A11,'Theo dõi'!$D$2:$D$601,"ChatGPT",'Theo dõi'!$B$2:$B$601,"Q20"))=0,"",(COUNTIFS('Theo dõi'!$A$2:$A$601,$A11,'Theo dõi'!$D$2:$D$601,"ChatGPT",'Theo dõi'!$F$2:$F$601,"Có")-COUNTIFS('Theo dõi'!$A$2:$A$601,$A11,'Theo dõi'!$D$2:$D$601,"ChatGPT",'Theo dõi'!$F$2:$F$601,"Có",'Theo dõi'!$B$2:$B$601,"Q18")-COUNTIFS('Theo dõi'!$A$2:$A$601,$A11,'Theo dõi'!$D$2:$D$601,"ChatGPT",'Theo dõi'!$F$2:$F$601,"Có",'Theo dõi'!$B$2:$B$601,"Q19")-COUNTIFS('Theo dõi'!$A$2:$A$601,$A11,'Theo dõi'!$D$2:$D$601,"ChatGPT",'Theo dõi'!$F$2:$F$601,"Có",'Theo dõi'!$B$2:$B$601,"Q20"))/(COUNTIFS('Theo dõi'!$A$2:$A$601,$A11,'Theo dõi'!$D$2:$D$601,"ChatGPT")-COUNTIFS('Theo dõi'!$A$2:$A$601,$A11,'Theo dõi'!$D$2:$D$601,"ChatGPT",'Theo dõi'!$B$2:$B$601,"Q18")-COUNTIFS('Theo dõi'!$A$2:$A$601,$A11,'Theo dõi'!$D$2:$D$601,"ChatGPT",'Theo dõi'!$B$2:$B$601,"Q19")-COUNTIFS('Theo dõi'!$A$2:$A$601,$A11,'Theo dõi'!$D$2:$D$601,"ChatGPT",'Theo dõi'!$B$2:$B$601,"Q20"))) | D11: =IF((COUNTIFS('Theo dõi'!$A$2:$A$601,$A11,'Theo dõi'!$D$2:$D$601,"Perplexity")-COUNTIFS('Theo dõi'!$A$2:$A$601,$A11,'Theo dõi'!$D$2:$D$601,"Perplexity",'Theo dõi'!$B$2:$B$601,"Q18")-COUNTIFS('Theo dõi'!$A$2:$A$601,$A11,'Theo dõi'!$D$2:$D$601,"Perplexity",'Theo dõi'!$B$2:$B$601,"Q19")-COUNTIFS('Theo dõi'!$A$2:$A$601,$A11,'Theo dõi'!$D$2:$D$601,"Perplexity",'Theo dõi'!$B$2:$B$601,"Q20"))=0,"",(COUNTIFS('Theo dõi'!$A$2:$A$601,$A11,'Theo dõi'!$D$2:$D$601,"Perplexity",'Theo dõi'!$F$2:$F$601,"Có")-COUNTIFS('Theo dõi'!$A$2:$A$601,$A11,'Theo dõi'!$D$2:$D$601,"Perplexity",'Theo dõi'!$F$2:$F$601,"Có",'Theo dõi'!$B$2:$B$601,"Q18")-COUNTIFS('Theo dõi'!$A$2:$A$601,$A11,'Theo dõi'!$D$2:$D$601,"Perplexity",'Theo dõi'!$F$2:$F$601,"Có",'Theo dõi'!$B$2:$B$601,"Q19")-COUNTIFS('Theo dõi'!$A$2:$A$601,$A11,'Theo dõi'!$D$2:$D$601,"Perplexity",'Theo dõi'!$F$2:$F$601,"Có",'Theo dõi'!$B$2:$B$601,"Q20"))/(COUNTIFS('Theo dõi'!$A$2:$A$601,$A11,'Theo dõi'!$D$2:$D$601,"Perplexity")-COUNTIFS('Theo dõi'!$A$2:$A$601,$A11,'Theo dõi'!$D$2:$D$601,"Perplexity",'Theo dõi'!$B$2:$B$601,"Q18")-COUNTIFS('Theo dõi'!$A$2:$A$601,$A11,'Theo dõi'!$D$2:$D$601,"Perplexity",'Theo dõi'!$B$2:$B$601,"Q19")-COUNTIFS('Theo dõi'!$A$2:$A$601,$A11,'Theo dõi'!$D$2:$D$601,"Perplexity",'Theo dõi'!$B$2:$B$601,"Q20"))) | E11: =IF((COUNTIFS('Theo dõi'!$A$2:$A$601,$A11,'Theo dõi'!$D$2:$D$601,"Gemini")-COUNTIFS('Theo dõi'!$A$2:$A$601,$A11,'Theo dõi'!$D$2:$D$601,"Gemini",'Theo dõi'!$B$2:$B$601,"Q18")-COUNTIFS('Theo dõi'!$A$2:$A$601,$A11,'Theo dõi'!$D$2:$D$601,"Gemini",'Theo dõi'!$B$2:$B$601,"Q19")-COUNTIFS('Theo dõi'!$A$2:$A$601,$A11,'Theo dõi'!$D$2:$D$601,"Gemini",'Theo dõi'!$B$2:$B$601,"Q20"))=0,"",(COUNTIFS('Theo dõi'!$A$2:$A$601,$A11,'Theo dõi'!$D$2:$D$601,"Gemini",'Theo dõi'!$F$2:$F$601,"Có")-COUNTIFS('Theo dõi'!$A$2:$A$601,$A11,'Theo dõi'!$D$2:$D$601,"Gemini",'Theo dõi'!$F$2:$F$601,"Có",'Theo dõi'!$B$2:$B$601,"Q18")-COUNTIFS('Theo dõi'!$A$2:$A$601,$A11,'Theo dõi'!$D$2:$D$601,"Gemini",'Theo dõi'!$F$2:$F$601,"Có",'Theo dõi'!$B$2:$B$601,"Q19")-COUNTIFS('Theo dõi'!$A$2:$A$601,$A11,'Theo dõi'!$D$2:$D$601,"Gemini",'Theo dõi'!$F$2:$F$601,"Có",'Theo dõi'!$B$2:$B$601,"Q20"))/(COUNTIFS('Theo dõi'!$A$2:$A$601,$A11,'Theo dõi'!$D$2:$D$601,"Gemini")-COUNTIFS('Theo dõi'!$A$2:$A$601,$A11,'Theo dõi'!$D$2:$D$601,"Gemini",'Theo dõi'!$B$2:$B$601,"Q18")-COUNTIFS('Theo dõi'!$A$2:$A$601,$A11,'Theo dõi'!$D$2:$D$601,"Gemini",'Theo dõi'!$B$2:$B$601,"Q19")-COUNTIFS('Theo dõi'!$A$2:$A$601,$A11,'Theo dõi'!$D$2:$D$601,"Gemini",'Theo dõi'!$B$2:$B$601,"Q20"))) | F11: =IF((COUNTIFS('Theo dõi'!$A$2:$A$601,$A11,'Theo dõi'!$D$2:$D$601,"Google AI Overview")-COUNTIFS('Theo dõi'!$A$2:$A$601,$A11,'Theo dõi'!$D$2:$D$601,"Google AI Overview",'Theo dõi'!$B$2:$B$601,"Q18")-COUNTIFS('Theo dõi'!$A$2:$A$601,$A11,'Theo dõi'!$D$2:$D$601,"Google AI Overview",'Theo dõi'!$B$2:$B$601,"Q19")-COUNTIFS('Theo dõi'!$A$2:$A$601,$A11,'Theo dõi'!$D$2:$D$601,"Google AI Overview",'Theo dõi'!$B$2:$B$601,"Q20"))=0,"",(COUNTIFS('Theo dõi'!$A$2:$A$601,$A11,'Theo dõi'!$D$2:$D$601,"Google AI Overview",'Theo dõi'!$F$2:$F$601,"Có")-COUNTIFS('Theo dõi'!$A$2:$A$601,$A11,'Theo dõi'!$D$2:$D$601,"Google AI Overview",'Theo dõi'!$F$2:$F$601,"Có",'Theo dõi'!$B$2:$B$601,"Q18")-COUNTIFS('Theo dõi'!$A$2:$A$601,$A11,'Theo dõi'!$D$2:$D$601,"Google AI Overview",'Theo dõi'!$F$2:$F$601,"Có",'Theo dõi'!$B$2:$B$601,"Q19")-COUNTIFS('Theo dõi'!$A$2:$A$601,$A11,'Theo dõi'!$D$2:$D$601,"Google AI Overview",'Theo dõi'!$F$2:$F$601,"Có",'Theo dõi'!$B$2:$B$601,"Q20"))/(COUNTIFS('Theo dõi'!$A$2:$A$601,$A11,'Theo dõi'!$D$2:$D$601,"Google AI Overview")-COUNTIFS('Theo dõi'!$A$2:$A$601,$A11,'Theo dõi'!$D$2:$D$601,"Google AI Overview",'Theo dõi'!$B$2:$B$601,"Q18")-COUNTIFS('Theo dõi'!$A$2:$A$601,$A11,'Theo dõi'!$D$2:$D$601,"Google AI Overview",'Theo dõi'!$B$2:$B$601,"Q19")-COUNTIFS('Theo dõi'!$A$2:$A$601,$A11,'Theo dõi'!$D$2:$D$601,"Google AI Overview",'Theo dõi'!$B$2:$B$601,"Q20"))) | G11: =IF((COUNTIFS('Theo dõi'!$A$2:$A$601,$A11,'Theo dõi'!$D$2:$D$601,"Copilot")-COUNTIFS('Theo dõi'!$A$2:$A$601,$A11,'Theo dõi'!$D$2:$D$601,"Copilot",'Theo dõi'!$B$2:$B$601,"Q18")-COUNTIFS('Theo dõi'!$A$2:$A$601,$A11,'Theo dõi'!$D$2:$D$601,"Copilot",'Theo dõi'!$B$2:$B$601,"Q19")-COUNTIFS('Theo dõi'!$A$2:$A$601,$A11,'Theo dõi'!$D$2:$D$601,"Copilot",'Theo dõi'!$B$2:$B$601,"Q20"))=0,"",(COUNTIFS('Theo dõi'!$A$2:$A$601,$A11,'Theo dõi'!$D$2:$D$601,"Copilot",'Theo dõi'!$F$2:$F$601,"Có")-COUNTIFS('Theo dõi'!$A$2:$A$601,$A11,'Theo dõi'!$D$2:$D$601,"Copilot",'Theo dõi'!$F$2:$F$601,"Có",'Theo dõi'!$B$2:$B$601,"Q18")-COUNTIFS('Theo dõi'!$A$2:$A$601,$A11,'Theo dõi'!$D$2:$D$601,"Copilot",'Theo dõi'!$F$2:$F$601,"Có",'Theo dõi'!$B$2:$B$601,"Q19")-COUNTIFS('Theo dõi'!$A$2:$A$601,$A11,'Theo dõi'!$D$2:$D$601,"Copilot",'Theo dõi'!$F$2:$F$601,"Có",'Theo dõi'!$B$2:$B$601,"Q20"))/(COUNTIFS('Theo dõi'!$A$2:$A$601,$A11,'Theo dõi'!$D$2:$D$601,"Copilot")-COUNTIFS('Theo dõi'!$A$2:$A$601,$A11,'Theo dõi'!$D$2:$D$601,"Copilot",'Theo dõi'!$B$2:$B$601,"Q18")-COUNTIFS('Theo dõi'!$A$2:$A$601,$A11,'Theo dõi'!$D$2:$D$601,"Copilot",'Theo dõi'!$B$2:$B$601,"Q19")-COUNTIFS('Theo dõi'!$A$2:$A$601,$A11,'Theo dõi'!$D$2:$D$601,"Copilot",'Theo dõi'!$B$2:$B$601,"Q20"))) | H11: =IF((COUNTIFS('Theo dõi'!$A$2:$A$601,$A11,'Theo dõi'!$D$2:$D$601,"<>")-COUNTIFS('Theo dõi'!$A$2:$A$601,$A11,'Theo dõi'!$D$2:$D$601,"<>",'Theo dõi'!$B$2:$B$601,"Q18")-COUNTIFS('Theo dõi'!$A$2:$A$601,$A11,'Theo dõi'!$D$2:$D$601,"<>",'Theo dõi'!$B$2:$B$601,"Q19")-COUNTIFS('Theo dõi'!$A$2:$A$601,$A11,'Theo dõi'!$D$2:$D$601,"<>",'Theo dõi'!$B$2:$B$601,"Q20"))=0,"",(COUNTIFS('Theo dõi'!$A$2:$A$601,$A11,'Theo dõi'!$D$2:$D$601,"<>",'Theo dõi'!$F$2:$F$601,"Có")-COUNTIFS('Theo dõi'!$A$2:$A$601,$A11,'Theo dõi'!$D$2:$D$601,"<>",'Theo dõi'!$F$2:$F$601,"Có",'Theo dõi'!$B$2:$B$601,"Q18")-COUNTIFS('Theo dõi'!$A$2:$A$601,$A11,'Theo dõi'!$D$2:$D$601,"<>",'Theo dõi'!$F$2:$F$601,"Có",'Theo dõi'!$B$2:$B$601,"Q19")-COUNTIFS('Theo dõi'!$A$2:$A$601,$A11,'Theo dõi'!$D$2:$D$601,"<>",'Theo dõi'!$F$2:$F$601,"Có",'Theo dõi'!$B$2:$B$601,"Q20"))/(COUNTIFS('Theo dõi'!$A$2:$A$601,$A11,'Theo dõi'!$D$2:$D$601,"<>")-COUNTIFS('Theo dõi'!$A$2:$A$601,$A11,'Theo dõi'!$D$2:$D$601,"<>",'Theo dõi'!$B$2:$B$601,"Q18")-COUNTIFS('Theo dõi'!$A$2:$A$601,$A11,'Theo dõi'!$D$2:$D$601,"<>",'Theo dõi'!$B$2:$B$601,"Q19")-COUNTIFS('Theo dõi'!$A$2:$A$601,$A11,'Theo dõi'!$D$2:$D$601,"<>",'Theo dõi'!$B$2:$B$601,"Q20")))
